{
 "cells": [
  {
   "cell_type": "code",
   "execution_count": null,
   "id": "0479738a",
   "metadata": {},
   "outputs": [],
   "source": [
    "import os\n",
    "\n",
    "import pandas as pd\n",
    "import torch\n",
    "import torch.nn as nn\n",
    "from comet_ml import Experiment\n",
    "import numpy as np\n",
    "\n",
    "import arccnet.models.cutouts.config as config\n",
    "import arccnet.models.dataset_utils as ut_d\n",
    "import arccnet.models.train_utils as ut_t\n",
    "import arccnet.visualisation.utils as ut_v\n",
    "\n",
    "from matplotlib import pyplot as plt\n",
    "\n",
    "from torch.utils.data import DataLoader, Dataset\n",
    "from sklearn.preprocessing import LabelEncoder\n",
    "from sklearn.utils.class_weight import compute_class_weight\n",
    "import timm\n",
    "\n",
    "from arccnet.models import labels as lbs\n",
    "import seaborn as sns"
   ]
  },
  {
   "cell_type": "code",
   "execution_count": null,
   "id": "af75849b",
   "metadata": {},
   "outputs": [],
   "source": [
    "# Generate run ID and weights directory\n",
    "run_id, weights_dir = ut_t.generate_run_id(config)\n",
    "\n",
    "# Create weights directory if it doesn't exist\n",
    "os.makedirs(weights_dir, exist_ok=True)"
   ]
  },
  {
   "cell_type": "code",
   "execution_count": 3,
   "id": "6a4926ab",
   "metadata": {},
   "outputs": [],
   "source": [
    "experiment = None\n",
    "if experiment:\n",
    "    # Initialize Comet experiment\n",
    "    run_comet = Experiment(project_name=config.project_name, workspace=\"arcaff\")\n",
    "    run_comet.add_tags([config.model_name])\n",
    "    run_comet.log_parameters(\n",
    "        {\n",
    "            \"model_name\": config.model_name,\n",
    "            \"batch_size\": config.batch_size,\n",
    "            \"GPU\": f\"GPU{config.gpu_index}_{torch.cuda.get_device_name()}\" if torch.cuda.is_available() else \"CPU\",\n",
    "            \"num_epochs\": config.num_epochs,\n",
    "            \"patience\": config.patience,\n",
    "        }\n",
    "    )\n",
    "    run_comet.log_code(config.__file__)\n",
    "    run_comet.log_code(ut_t.__file__)\n",
    "    run_comet.add_tags(config.other_tags)"
   ]
  },
  {
   "cell_type": "code",
   "execution_count": 4,
   "id": "dd326617",
   "metadata": {},
   "outputs": [
    {
     "data": {
      "text/html": [
       "<div>\n",
       "<style scoped>\n",
       "    .dataframe tbody tr th:only-of-type {\n",
       "        vertical-align: middle;\n",
       "    }\n",
       "\n",
       "    .dataframe tbody tr th {\n",
       "        vertical-align: top;\n",
       "    }\n",
       "\n",
       "    .dataframe thead th {\n",
       "        text-align: right;\n",
       "    }\n",
       "</style>\n",
       "<table border=\"1\" class=\"dataframe\">\n",
       "  <thead>\n",
       "    <tr style=\"text-align: right;\">\n",
       "      <th></th>\n",
       "      <th>target_time.jd1</th>\n",
       "      <th>target_time.jd2</th>\n",
       "      <th>datetime.jd1</th>\n",
       "      <th>datetime.jd2</th>\n",
       "      <th>instrument</th>\n",
       "      <th>path</th>\n",
       "      <th>processed_path_image</th>\n",
       "      <th>target_time_arc.jd1</th>\n",
       "      <th>target_time_arc.jd2</th>\n",
       "      <th>datetime_arc.jd1</th>\n",
       "      <th>...</th>\n",
       "      <th>record_HARPNUM_arc</th>\n",
       "      <th>record_HARPNUM_arc.mask</th>\n",
       "      <th>quicklook_path</th>\n",
       "      <th>quicklook_path.mask</th>\n",
       "      <th>time</th>\n",
       "      <th>datetime</th>\n",
       "      <th>width</th>\n",
       "      <th>height</th>\n",
       "      <th>grouped_labels</th>\n",
       "      <th>Index</th>\n",
       "    </tr>\n",
       "  </thead>\n",
       "  <tbody>\n",
       "    <tr>\n",
       "      <th>30</th>\n",
       "      <td>2450262.0</td>\n",
       "      <td>0.5</td>\n",
       "      <td>2450263.0</td>\n",
       "      <td>-0.498958</td>\n",
       "      <td>MDI</td>\n",
       "      <td>arccnet_data/02_intermediate/data/mag/fits/mdi...</td>\n",
       "      <td>arccnet_data/03_processed/data/mag/fits/mdi/md...</td>\n",
       "      <td>2450262.0</td>\n",
       "      <td>0.5</td>\n",
       "      <td>2450263.0</td>\n",
       "      <td>...</td>\n",
       "      <td>0</td>\n",
       "      <td>True</td>\n",
       "      <td>arccnet_data/04_final/data/region_detection/qu...</td>\n",
       "      <td>False</td>\n",
       "      <td>2.450263e+06</td>\n",
       "      <td>1996-06-28 00:01:30.000</td>\n",
       "      <td>0.108398</td>\n",
       "      <td>0.062500</td>\n",
       "      <td>Alpha</td>\n",
       "      <td>0</td>\n",
       "    </tr>\n",
       "    <tr>\n",
       "      <th>31</th>\n",
       "      <td>2450262.0</td>\n",
       "      <td>0.5</td>\n",
       "      <td>2450263.0</td>\n",
       "      <td>-0.498958</td>\n",
       "      <td>MDI</td>\n",
       "      <td>arccnet_data/02_intermediate/data/mag/fits/mdi...</td>\n",
       "      <td>arccnet_data/03_processed/data/mag/fits/mdi/md...</td>\n",
       "      <td>2450262.0</td>\n",
       "      <td>0.5</td>\n",
       "      <td>2450263.0</td>\n",
       "      <td>...</td>\n",
       "      <td>0</td>\n",
       "      <td>True</td>\n",
       "      <td>arccnet_data/04_final/data/region_detection/qu...</td>\n",
       "      <td>False</td>\n",
       "      <td>2.450263e+06</td>\n",
       "      <td>1996-06-28 00:01:30.000</td>\n",
       "      <td>0.082031</td>\n",
       "      <td>0.058594</td>\n",
       "      <td>Alpha</td>\n",
       "      <td>1</td>\n",
       "    </tr>\n",
       "    <tr>\n",
       "      <th>32</th>\n",
       "      <td>2450264.0</td>\n",
       "      <td>-0.5</td>\n",
       "      <td>2450264.0</td>\n",
       "      <td>-0.498958</td>\n",
       "      <td>MDI</td>\n",
       "      <td>arccnet_data/02_intermediate/data/mag/fits/mdi...</td>\n",
       "      <td>arccnet_data/03_processed/data/mag/fits/mdi/md...</td>\n",
       "      <td>2450264.0</td>\n",
       "      <td>-0.5</td>\n",
       "      <td>2450264.0</td>\n",
       "      <td>...</td>\n",
       "      <td>0</td>\n",
       "      <td>True</td>\n",
       "      <td>arccnet_data/04_final/data/region_detection/qu...</td>\n",
       "      <td>False</td>\n",
       "      <td>2.450264e+06</td>\n",
       "      <td>1996-06-29 00:01:30.000</td>\n",
       "      <td>0.068359</td>\n",
       "      <td>0.059570</td>\n",
       "      <td>Alpha</td>\n",
       "      <td>2</td>\n",
       "    </tr>\n",
       "    <tr>\n",
       "      <th>33</th>\n",
       "      <td>2450264.0</td>\n",
       "      <td>-0.5</td>\n",
       "      <td>2450264.0</td>\n",
       "      <td>-0.498958</td>\n",
       "      <td>MDI</td>\n",
       "      <td>arccnet_data/02_intermediate/data/mag/fits/mdi...</td>\n",
       "      <td>arccnet_data/03_processed/data/mag/fits/mdi/md...</td>\n",
       "      <td>2450264.0</td>\n",
       "      <td>-0.5</td>\n",
       "      <td>2450264.0</td>\n",
       "      <td>...</td>\n",
       "      <td>0</td>\n",
       "      <td>True</td>\n",
       "      <td>arccnet_data/04_final/data/region_detection/qu...</td>\n",
       "      <td>False</td>\n",
       "      <td>2.450264e+06</td>\n",
       "      <td>1996-06-29 00:01:30.000</td>\n",
       "      <td>0.110352</td>\n",
       "      <td>0.060547</td>\n",
       "      <td>Alpha</td>\n",
       "      <td>3</td>\n",
       "    </tr>\n",
       "    <tr>\n",
       "      <th>34</th>\n",
       "      <td>2450264.0</td>\n",
       "      <td>0.5</td>\n",
       "      <td>2450265.0</td>\n",
       "      <td>-0.498958</td>\n",
       "      <td>MDI</td>\n",
       "      <td>arccnet_data/02_intermediate/data/mag/fits/mdi...</td>\n",
       "      <td>arccnet_data/03_processed/data/mag/fits/mdi/md...</td>\n",
       "      <td>2450264.0</td>\n",
       "      <td>0.5</td>\n",
       "      <td>2450265.0</td>\n",
       "      <td>...</td>\n",
       "      <td>0</td>\n",
       "      <td>True</td>\n",
       "      <td>arccnet_data/04_final/data/region_detection/qu...</td>\n",
       "      <td>False</td>\n",
       "      <td>2.450265e+06</td>\n",
       "      <td>1996-06-30 00:01:30.000</td>\n",
       "      <td>0.051758</td>\n",
       "      <td>0.059570</td>\n",
       "      <td>Alpha</td>\n",
       "      <td>4</td>\n",
       "    </tr>\n",
       "    <tr>\n",
       "      <th>...</th>\n",
       "      <td>...</td>\n",
       "      <td>...</td>\n",
       "      <td>...</td>\n",
       "      <td>...</td>\n",
       "      <td>...</td>\n",
       "      <td>...</td>\n",
       "      <td>...</td>\n",
       "      <td>...</td>\n",
       "      <td>...</td>\n",
       "      <td>...</td>\n",
       "      <td>...</td>\n",
       "      <td>...</td>\n",
       "      <td>...</td>\n",
       "      <td>...</td>\n",
       "      <td>...</td>\n",
       "      <td>...</td>\n",
       "      <td>...</td>\n",
       "      <td>...</td>\n",
       "      <td>...</td>\n",
       "      <td>...</td>\n",
       "      <td>...</td>\n",
       "    </tr>\n",
       "    <tr>\n",
       "      <th>27389</th>\n",
       "      <td>2459818.0</td>\n",
       "      <td>0.5</td>\n",
       "      <td>2459818.0</td>\n",
       "      <td>0.499111</td>\n",
       "      <td>HMI</td>\n",
       "      <td>arccnet_data/02_intermediate/data/mag/fits/hmi...</td>\n",
       "      <td>arccnet_data/03_processed/data/mag/fits/hmi/hm...</td>\n",
       "      <td>2459818.0</td>\n",
       "      <td>0.5</td>\n",
       "      <td>2459818.0</td>\n",
       "      <td>...</td>\n",
       "      <td>8540</td>\n",
       "      <td>False</td>\n",
       "      <td>arccnet_data/04_final/data/region_detection/qu...</td>\n",
       "      <td>False</td>\n",
       "      <td>2.459818e+06</td>\n",
       "      <td>2022-08-26 23:58:43.200</td>\n",
       "      <td>0.146240</td>\n",
       "      <td>0.056396</td>\n",
       "      <td>Beta</td>\n",
       "      <td>4927</td>\n",
       "    </tr>\n",
       "    <tr>\n",
       "      <th>27390</th>\n",
       "      <td>2459820.0</td>\n",
       "      <td>-0.5</td>\n",
       "      <td>2459819.0</td>\n",
       "      <td>0.499110</td>\n",
       "      <td>HMI</td>\n",
       "      <td>arccnet_data/02_intermediate/data/mag/fits/hmi...</td>\n",
       "      <td>arccnet_data/03_processed/data/mag/fits/hmi/hm...</td>\n",
       "      <td>2459820.0</td>\n",
       "      <td>-0.5</td>\n",
       "      <td>2459819.0</td>\n",
       "      <td>...</td>\n",
       "      <td>8540</td>\n",
       "      <td>False</td>\n",
       "      <td>arccnet_data/04_final/data/region_detection/qu...</td>\n",
       "      <td>False</td>\n",
       "      <td>2.459819e+06</td>\n",
       "      <td>2022-08-27 23:58:43.100</td>\n",
       "      <td>0.145508</td>\n",
       "      <td>0.057373</td>\n",
       "      <td>Beta</td>\n",
       "      <td>4928</td>\n",
       "    </tr>\n",
       "    <tr>\n",
       "      <th>27391</th>\n",
       "      <td>2459820.0</td>\n",
       "      <td>-0.5</td>\n",
       "      <td>2459819.0</td>\n",
       "      <td>0.499110</td>\n",
       "      <td>HMI</td>\n",
       "      <td>arccnet_data/02_intermediate/data/mag/fits/hmi...</td>\n",
       "      <td>arccnet_data/03_processed/data/mag/fits/hmi/hm...</td>\n",
       "      <td>2459820.0</td>\n",
       "      <td>-0.5</td>\n",
       "      <td>2459819.0</td>\n",
       "      <td>...</td>\n",
       "      <td>8546</td>\n",
       "      <td>False</td>\n",
       "      <td>arccnet_data/04_final/data/region_detection/qu...</td>\n",
       "      <td>False</td>\n",
       "      <td>2.459819e+06</td>\n",
       "      <td>2022-08-27 23:58:43.100</td>\n",
       "      <td>0.186279</td>\n",
       "      <td>0.108398</td>\n",
       "      <td>Beta</td>\n",
       "      <td>4929</td>\n",
       "    </tr>\n",
       "    <tr>\n",
       "      <th>27392</th>\n",
       "      <td>2459820.0</td>\n",
       "      <td>-0.5</td>\n",
       "      <td>2459819.0</td>\n",
       "      <td>0.499110</td>\n",
       "      <td>HMI</td>\n",
       "      <td>arccnet_data/02_intermediate/data/mag/fits/hmi...</td>\n",
       "      <td>arccnet_data/03_processed/data/mag/fits/hmi/hm...</td>\n",
       "      <td>2459820.0</td>\n",
       "      <td>-0.5</td>\n",
       "      <td>2459819.0</td>\n",
       "      <td>...</td>\n",
       "      <td>8539</td>\n",
       "      <td>False</td>\n",
       "      <td>arccnet_data/04_final/data/region_detection/qu...</td>\n",
       "      <td>False</td>\n",
       "      <td>2.459819e+06</td>\n",
       "      <td>2022-08-27 23:58:43.100</td>\n",
       "      <td>0.085937</td>\n",
       "      <td>0.064697</td>\n",
       "      <td>Beta</td>\n",
       "      <td>4930</td>\n",
       "    </tr>\n",
       "    <tr>\n",
       "      <th>27393</th>\n",
       "      <td>2459820.0</td>\n",
       "      <td>-0.5</td>\n",
       "      <td>2459819.0</td>\n",
       "      <td>0.499110</td>\n",
       "      <td>HMI</td>\n",
       "      <td>arccnet_data/02_intermediate/data/mag/fits/hmi...</td>\n",
       "      <td>arccnet_data/03_processed/data/mag/fits/hmi/hm...</td>\n",
       "      <td>2459820.0</td>\n",
       "      <td>-0.5</td>\n",
       "      <td>2459819.0</td>\n",
       "      <td>...</td>\n",
       "      <td>8543</td>\n",
       "      <td>False</td>\n",
       "      <td>arccnet_data/04_final/data/region_detection/qu...</td>\n",
       "      <td>False</td>\n",
       "      <td>2.459819e+06</td>\n",
       "      <td>2022-08-27 23:58:43.100</td>\n",
       "      <td>0.120850</td>\n",
       "      <td>0.090576</td>\n",
       "      <td>Alpha</td>\n",
       "      <td>4931</td>\n",
       "    </tr>\n",
       "  </tbody>\n",
       "</table>\n",
       "<p>4932 rows × 38 columns</p>\n",
       "</div>"
      ],
      "text/plain": [
       "       target_time.jd1  target_time.jd2  datetime.jd1  datetime.jd2  \\\n",
       "30           2450262.0              0.5     2450263.0     -0.498958   \n",
       "31           2450262.0              0.5     2450263.0     -0.498958   \n",
       "32           2450264.0             -0.5     2450264.0     -0.498958   \n",
       "33           2450264.0             -0.5     2450264.0     -0.498958   \n",
       "34           2450264.0              0.5     2450265.0     -0.498958   \n",
       "...                ...              ...           ...           ...   \n",
       "27389        2459818.0              0.5     2459818.0      0.499111   \n",
       "27390        2459820.0             -0.5     2459819.0      0.499110   \n",
       "27391        2459820.0             -0.5     2459819.0      0.499110   \n",
       "27392        2459820.0             -0.5     2459819.0      0.499110   \n",
       "27393        2459820.0             -0.5     2459819.0      0.499110   \n",
       "\n",
       "      instrument                                               path  \\\n",
       "30           MDI  arccnet_data/02_intermediate/data/mag/fits/mdi...   \n",
       "31           MDI  arccnet_data/02_intermediate/data/mag/fits/mdi...   \n",
       "32           MDI  arccnet_data/02_intermediate/data/mag/fits/mdi...   \n",
       "33           MDI  arccnet_data/02_intermediate/data/mag/fits/mdi...   \n",
       "34           MDI  arccnet_data/02_intermediate/data/mag/fits/mdi...   \n",
       "...          ...                                                ...   \n",
       "27389        HMI  arccnet_data/02_intermediate/data/mag/fits/hmi...   \n",
       "27390        HMI  arccnet_data/02_intermediate/data/mag/fits/hmi...   \n",
       "27391        HMI  arccnet_data/02_intermediate/data/mag/fits/hmi...   \n",
       "27392        HMI  arccnet_data/02_intermediate/data/mag/fits/hmi...   \n",
       "27393        HMI  arccnet_data/02_intermediate/data/mag/fits/hmi...   \n",
       "\n",
       "                                    processed_path_image  target_time_arc.jd1  \\\n",
       "30     arccnet_data/03_processed/data/mag/fits/mdi/md...            2450262.0   \n",
       "31     arccnet_data/03_processed/data/mag/fits/mdi/md...            2450262.0   \n",
       "32     arccnet_data/03_processed/data/mag/fits/mdi/md...            2450264.0   \n",
       "33     arccnet_data/03_processed/data/mag/fits/mdi/md...            2450264.0   \n",
       "34     arccnet_data/03_processed/data/mag/fits/mdi/md...            2450264.0   \n",
       "...                                                  ...                  ...   \n",
       "27389  arccnet_data/03_processed/data/mag/fits/hmi/hm...            2459818.0   \n",
       "27390  arccnet_data/03_processed/data/mag/fits/hmi/hm...            2459820.0   \n",
       "27391  arccnet_data/03_processed/data/mag/fits/hmi/hm...            2459820.0   \n",
       "27392  arccnet_data/03_processed/data/mag/fits/hmi/hm...            2459820.0   \n",
       "27393  arccnet_data/03_processed/data/mag/fits/hmi/hm...            2459820.0   \n",
       "\n",
       "       target_time_arc.jd2  datetime_arc.jd1  ...  record_HARPNUM_arc  \\\n",
       "30                     0.5         2450263.0  ...                   0   \n",
       "31                     0.5         2450263.0  ...                   0   \n",
       "32                    -0.5         2450264.0  ...                   0   \n",
       "33                    -0.5         2450264.0  ...                   0   \n",
       "34                     0.5         2450265.0  ...                   0   \n",
       "...                    ...               ...  ...                 ...   \n",
       "27389                  0.5         2459818.0  ...                8540   \n",
       "27390                 -0.5         2459819.0  ...                8540   \n",
       "27391                 -0.5         2459819.0  ...                8546   \n",
       "27392                 -0.5         2459819.0  ...                8539   \n",
       "27393                 -0.5         2459819.0  ...                8543   \n",
       "\n",
       "      record_HARPNUM_arc.mask  \\\n",
       "30                       True   \n",
       "31                       True   \n",
       "32                       True   \n",
       "33                       True   \n",
       "34                       True   \n",
       "...                       ...   \n",
       "27389                   False   \n",
       "27390                   False   \n",
       "27391                   False   \n",
       "27392                   False   \n",
       "27393                   False   \n",
       "\n",
       "                                          quicklook_path quicklook_path.mask  \\\n",
       "30     arccnet_data/04_final/data/region_detection/qu...               False   \n",
       "31     arccnet_data/04_final/data/region_detection/qu...               False   \n",
       "32     arccnet_data/04_final/data/region_detection/qu...               False   \n",
       "33     arccnet_data/04_final/data/region_detection/qu...               False   \n",
       "34     arccnet_data/04_final/data/region_detection/qu...               False   \n",
       "...                                                  ...                 ...   \n",
       "27389  arccnet_data/04_final/data/region_detection/qu...               False   \n",
       "27390  arccnet_data/04_final/data/region_detection/qu...               False   \n",
       "27391  arccnet_data/04_final/data/region_detection/qu...               False   \n",
       "27392  arccnet_data/04_final/data/region_detection/qu...               False   \n",
       "27393  arccnet_data/04_final/data/region_detection/qu...               False   \n",
       "\n",
       "               time                datetime     width    height  \\\n",
       "30     2.450263e+06 1996-06-28 00:01:30.000  0.108398  0.062500   \n",
       "31     2.450263e+06 1996-06-28 00:01:30.000  0.082031  0.058594   \n",
       "32     2.450264e+06 1996-06-29 00:01:30.000  0.068359  0.059570   \n",
       "33     2.450264e+06 1996-06-29 00:01:30.000  0.110352  0.060547   \n",
       "34     2.450265e+06 1996-06-30 00:01:30.000  0.051758  0.059570   \n",
       "...             ...                     ...       ...       ...   \n",
       "27389  2.459818e+06 2022-08-26 23:58:43.200  0.146240  0.056396   \n",
       "27390  2.459819e+06 2022-08-27 23:58:43.100  0.145508  0.057373   \n",
       "27391  2.459819e+06 2022-08-27 23:58:43.100  0.186279  0.108398   \n",
       "27392  2.459819e+06 2022-08-27 23:58:43.100  0.085937  0.064697   \n",
       "27393  2.459819e+06 2022-08-27 23:58:43.100  0.120850  0.090576   \n",
       "\n",
       "      grouped_labels  Index  \n",
       "30             Alpha      0  \n",
       "31             Alpha      1  \n",
       "32             Alpha      2  \n",
       "33             Alpha      3  \n",
       "34             Alpha      4  \n",
       "...              ...    ...  \n",
       "27389           Beta   4927  \n",
       "27390           Beta   4928  \n",
       "27391           Beta   4929  \n",
       "27392           Beta   4930  \n",
       "27393          Alpha   4931  \n",
       "\n",
       "[4932 rows x 38 columns]"
      ]
     },
     "execution_count": 4,
     "metadata": {},
     "output_type": "execute_result"
    }
   ],
   "source": [
    "# Load Dataset\n",
    "base_dir = '/ARCAFF/data/cutouts_from_fulldisk/'\n",
    "df = pd.read_parquet(os.path.join(base_dir, 'dataframe.parquet'))\n",
    "\n",
    "label_mapping = {\n",
    "    \"Alpha\": \"Alpha\",\n",
    "    \"Beta\": \"Beta\",\n",
    "    \"Beta-Delta\": \"Beta\",\n",
    "    \"Beta-Gamma\": \"Beta-Gamma\",\n",
    "    \"Beta-Gamma-Delta\": \"Beta-Gamma\",\n",
    "    \"Gamma\": None,\n",
    "    \"Gamma-Delta\": None,\n",
    "}\n",
    "\n",
    "df[\"grouped_labels\"] = df[\"magnetic_class\"].map(label_mapping)\n",
    "df['Index'] = range(len(df))\n",
    "df"
   ]
  },
  {
   "cell_type": "code",
   "execution_count": 5,
   "id": "fe2a9e40",
   "metadata": {},
   "outputs": [
    {
     "name": "stderr",
     "output_type": "stream",
     "text": [
      "/ARCAFF/ARCCnet/arccnet/models/dataset_utils.py:228: SettingWithCopyWarning: \n",
      "A value is trying to be set on a copy of a slice from a DataFrame.\n",
      "Try using .loc[row_indexer,col_indexer] = value instead\n",
      "\n",
      "See the caveats in the documentation: https://pandas.pydata.org/pandas-docs/stable/user_guide/indexing.html#returning-a-view-versus-a-copy\n",
      "  X.loc[train_df.index, f\"Fold {fold}\"] = \"train\"\n",
      "/ARCAFF/ARCCnet/arccnet/models/dataset_utils.py:228: SettingWithCopyWarning: \n",
      "A value is trying to be set on a copy of a slice from a DataFrame.\n",
      "Try using .loc[row_indexer,col_indexer] = value instead\n",
      "\n",
      "See the caveats in the documentation: https://pandas.pydata.org/pandas-docs/stable/user_guide/indexing.html#returning-a-view-versus-a-copy\n",
      "  X.loc[train_df.index, f\"Fold {fold}\"] = \"train\"\n",
      "/ARCAFF/ARCCnet/arccnet/models/dataset_utils.py:228: SettingWithCopyWarning: \n",
      "A value is trying to be set on a copy of a slice from a DataFrame.\n",
      "Try using .loc[row_indexer,col_indexer] = value instead\n",
      "\n",
      "See the caveats in the documentation: https://pandas.pydata.org/pandas-docs/stable/user_guide/indexing.html#returning-a-view-versus-a-copy\n",
      "  X.loc[train_df.index, f\"Fold {fold}\"] = \"train\"\n",
      "/ARCAFF/ARCCnet/arccnet/models/dataset_utils.py:228: SettingWithCopyWarning: \n",
      "A value is trying to be set on a copy of a slice from a DataFrame.\n",
      "Try using .loc[row_indexer,col_indexer] = value instead\n",
      "\n",
      "See the caveats in the documentation: https://pandas.pydata.org/pandas-docs/stable/user_guide/indexing.html#returning-a-view-versus-a-copy\n",
      "  X.loc[train_df.index, f\"Fold {fold}\"] = \"train\"\n",
      "/ARCAFF/ARCCnet/arccnet/models/dataset_utils.py:228: SettingWithCopyWarning: \n",
      "A value is trying to be set on a copy of a slice from a DataFrame.\n",
      "Try using .loc[row_indexer,col_indexer] = value instead\n",
      "\n",
      "See the caveats in the documentation: https://pandas.pydata.org/pandas-docs/stable/user_guide/indexing.html#returning-a-view-versus-a-copy\n",
      "  X.loc[train_df.index, f\"Fold {fold}\"] = \"train\"\n"
     ]
    }
   ],
   "source": [
    "split_df = df.dropna(subset=[\"grouped_labels\", \"NOAA\"])\n",
    "fold_df = ut_d.split_data(split_df, label_col=\"grouped_labels\", group_col=\"NOAA\", random_state=42)\n",
    "df_tr = ut_d.assign_fold_sets(df, fold_df)"
   ]
  },
  {
   "cell_type": "code",
   "execution_count": 25,
   "id": "fead14f0",
   "metadata": {},
   "outputs": [
    {
     "name": "stdout",
     "output_type": "stream",
     "text": [
      "Mapping: {'Alpha': 0, 'Beta': 1, 'Beta-Gamma': 2, None: 3}\n"
     ]
    }
   ],
   "source": [
    "data = np.load(os.path.join(base_dir, 'processed_data.npz'))\n",
    "images = data['images']\n",
    "labels = np.array(df_tr['grouped_labels'])\n",
    "\n",
    "label_encoder = LabelEncoder()\n",
    "encoded_labels = label_encoder.fit_transform(labels)\n",
    "\n",
    "df_tr['encoded_labels'] = encoded_labels\n",
    "\n",
    "fold_n = 1\n",
    "train_df = df_tr[df_tr[f'Fold {fold_n}']=='train']\n",
    "val_df = df_tr[df_tr[f'Fold {fold_n}']=='val']\n",
    "test_df = df_tr[df_tr[f'Fold {fold_n}']=='test']\n",
    "\n",
    "print(\"Mapping:\", dict(zip(label_encoder.classes_, range(len(label_encoder.classes_)))))"
   ]
  },
  {
   "cell_type": "code",
   "execution_count": 38,
   "id": "0a47ea3c",
   "metadata": {},
   "outputs": [
    {
     "data": {
      "text/plain": [
       "4932"
      ]
     },
     "execution_count": 38,
     "metadata": {},
     "output_type": "execute_result"
    }
   ],
   "source": [
    "len(images)"
   ]
  },
  {
   "cell_type": "code",
   "execution_count": 79,
   "id": "d3791e14",
   "metadata": {},
   "outputs": [],
   "source": [
    "class Cutouts(Dataset):\n",
    "\n",
    "    def __init__(\n",
    "        self, images, df, transform=None\n",
    "    ):\n",
    "        self.images = images\n",
    "        self.df = df\n",
    "        self.transform = transform\n",
    "\n",
    "    def __len__(self):\n",
    "        return len(self.df)\n",
    "\n",
    "    def __getitem__(self, idx):\n",
    "        row = self.df.iloc[idx]\n",
    "        image_idx = row['Index']\n",
    "        image = self.images[image_idx]\n",
    "        label = row['encoded_labels']\n",
    "        \n",
    "        image = torch.from_numpy(image).unsqueeze(0)\n",
    "        image = image.to(dtype=torch.float32)\n",
    "\n",
    "        if self.transform:\n",
    "            image = self.transform(image)\n",
    "\n",
    "        return image, label"
   ]
  },
  {
   "cell_type": "code",
   "execution_count": 80,
   "id": "c50fa4a1",
   "metadata": {},
   "outputs": [],
   "source": [
    "num_classes = 3\n",
    "\n",
    "train_dataset = Cutouts(images, train_df, config.train_transforms)\n",
    "val_dataset = Cutouts(images, val_df, config.val_transforms)\n",
    "test_dataset = Cutouts(images, test_df, config.val_transforms)"
   ]
  },
  {
   "cell_type": "code",
   "execution_count": 81,
   "id": "30e5ebf2",
   "metadata": {},
   "outputs": [],
   "source": [
    "train_loader = DataLoader(\n",
    "    train_dataset, batch_size=config.batch_size, shuffle=True, num_workers=config.num_workers, pin_memory=True\n",
    ")\n",
    "val_loader = DataLoader(\n",
    "    val_dataset, batch_size=config.batch_size, shuffle=False, num_workers=config.num_workers, pin_memory=True\n",
    ")\n",
    "test_loader = DataLoader(\n",
    "    test_dataset, batch_size=config.batch_size, shuffle=False, num_workers=config.num_workers, pin_memory=True\n",
    ")"
   ]
  },
  {
   "cell_type": "code",
   "execution_count": 82,
   "id": "4b98a3c2",
   "metadata": {},
   "outputs": [
    {
     "name": "stdout",
     "output_type": "stream",
     "text": [
      "Number of trainable parameters: 302780419\n"
     ]
    }
   ],
   "source": [
    "model = timm.create_model(config.model_name, pretrained=config.pretrained, num_classes=num_classes, in_chans=1)\n",
    "ut_t.replace_activations(model, nn.ReLU, nn.LeakyReLU, negative_slope=0.01)\n",
    "device = torch.device(config.device) if torch.cuda.is_available() else torch.device(\"cpu\")\n",
    "model.to(device)\n",
    "num_params = ut_t.count_trainable_parameters(model, print_num=True)"
   ]
  },
  {
   "cell_type": "code",
   "execution_count": 83,
   "id": "f1c05e42",
   "metadata": {},
   "outputs": [],
   "source": [
    "class_weights = compute_class_weight(\n",
    "    \"balanced\", classes=np.unique(train_df[\"encoded_labels\"].values), y=train_df[\"encoded_labels\"].values\n",
    ")"
   ]
  },
  {
   "cell_type": "code",
   "execution_count": 84,
   "id": "2be1ed47",
   "metadata": {},
   "outputs": [],
   "source": [
    "alpha_tensor = torch.tensor(class_weights, dtype=torch.float).to(device)\n",
    "criterion = torch.nn.CrossEntropyLoss(weight=alpha_tensor)\n",
    "optimizer = torch.optim.Adam(model.parameters(), lr=config.learning_rate)\n",
    "# Get the CUDA version\n",
    "cuda_version = torch.version.cuda\n",
    "if cuda_version and float(cuda_version) < 11.8:\n",
    "    scaler = torch.cuda.amp.GradScaler()\n",
    "else:\n",
    "    scaler = torch.amp.GradScaler(\"cuda\")"
   ]
  },
  {
   "cell_type": "code",
   "execution_count": 85,
   "id": "138d8b34",
   "metadata": {},
   "outputs": [
    {
     "name": "stderr",
     "output_type": "stream",
     "text": [
      "Epoch 1: 100%|██████████| 223/223 [00:53<00:00,  4.15batch/s]\n",
      "Validation: 100%|██████████| 61/61 [00:16<00:00,  3.78batch/s]\n"
     ]
    },
    {
     "name": "stdout",
     "output_type": "stream",
     "text": [
      "Epoch Summary 1: Train Loss: 17.7377, Train Acc.: 0.3976, Val. Loss: 0.9339, Val. Acc.: 0.3515, Val. Precision: 0.2236, Val. Recall: 0.5621, Val. F1: 0.3176\n"
     ]
    },
    {
     "name": "stderr",
     "output_type": "stream",
     "text": [
      "Epoch 2: 100%|██████████| 223/223 [00:50<00:00,  4.37batch/s]\n",
      "Validation: 100%|██████████| 61/61 [00:16<00:00,  3.77batch/s]\n"
     ]
    },
    {
     "name": "stdout",
     "output_type": "stream",
     "text": [
      "Epoch Summary 2: Train Loss: 14.7424, Train Acc.: 0.4826, Val. Loss: 0.7770, Val. Acc.: 0.6649, Val. Precision: 0.6258, Val. Recall: 0.6694, Val. F1: 0.6431\n"
     ]
    },
    {
     "name": "stderr",
     "output_type": "stream",
     "text": [
      "Epoch 3: 100%|██████████| 223/223 [00:51<00:00,  4.35batch/s]\n",
      "Validation: 100%|██████████| 61/61 [00:16<00:00,  3.77batch/s]\n"
     ]
    },
    {
     "name": "stdout",
     "output_type": "stream",
     "text": [
      "Early Stopping: 1/10 without improvement.\n",
      "Epoch Summary 3: Train Loss: 13.6721, Train Acc.: 0.5252, Val. Loss: 0.7990, Val. Acc.: 0.6608, Val. Precision: 0.7303, Val. Recall: 0.5771, Val. F1: 0.5878\n"
     ]
    },
    {
     "name": "stderr",
     "output_type": "stream",
     "text": [
      "Epoch 4: 100%|██████████| 223/223 [00:51<00:00,  4.35batch/s]\n",
      "Validation: 100%|██████████| 61/61 [00:16<00:00,  3.75batch/s]\n"
     ]
    },
    {
     "name": "stdout",
     "output_type": "stream",
     "text": [
      "Early Stopping: 2/10 without improvement.\n",
      "Epoch Summary 4: Train Loss: 12.4560, Train Acc.: 0.5813, Val. Loss: 0.6872, Val. Acc.: 0.6412, Val. Precision: 0.6088, Val. Recall: 0.6935, Val. F1: 0.6287\n"
     ]
    },
    {
     "name": "stderr",
     "output_type": "stream",
     "text": [
      "Epoch 5: 100%|██████████| 223/223 [00:51<00:00,  4.35batch/s]\n",
      "Validation: 100%|██████████| 61/61 [00:16<00:00,  3.75batch/s]\n"
     ]
    },
    {
     "name": "stdout",
     "output_type": "stream",
     "text": [
      "Early Stopping: 3/10 without improvement.\n",
      "Epoch Summary 5: Train Loss: 12.2230, Train Acc.: 0.5838, Val. Loss: 0.7158, Val. Acc.: 0.6052, Val. Precision: 0.5899, Val. Recall: 0.6546, Val. F1: 0.5763\n"
     ]
    },
    {
     "name": "stderr",
     "output_type": "stream",
     "text": [
      "Epoch 6: 100%|██████████| 223/223 [00:51<00:00,  4.35batch/s]\n",
      "Validation: 100%|██████████| 61/61 [00:16<00:00,  3.78batch/s]\n"
     ]
    },
    {
     "name": "stdout",
     "output_type": "stream",
     "text": [
      "Early Stopping: 4/10 without improvement.\n",
      "Epoch Summary 6: Train Loss: 12.0433, Train Acc.: 0.5771, Val. Loss: 0.7609, Val. Acc.: 0.5392, Val. Precision: 0.5588, Val. Recall: 0.6455, Val. F1: 0.5345\n"
     ]
    },
    {
     "name": "stderr",
     "output_type": "stream",
     "text": [
      "Epoch 7: 100%|██████████| 223/223 [00:51<00:00,  4.36batch/s]\n",
      "Validation: 100%|██████████| 61/61 [00:16<00:00,  3.76batch/s]\n"
     ]
    },
    {
     "name": "stdout",
     "output_type": "stream",
     "text": [
      "Early Stopping: 5/10 without improvement.\n",
      "Epoch Summary 7: Train Loss: 12.0811, Train Acc.: 0.5903, Val. Loss: 0.9654, Val. Acc.: 0.3701, Val. Precision: 0.5358, Val. Recall: 0.5736, Val. F1: 0.3874\n"
     ]
    },
    {
     "name": "stderr",
     "output_type": "stream",
     "text": [
      "Epoch 8: 100%|██████████| 223/223 [00:51<00:00,  4.35batch/s]\n",
      "Validation: 100%|██████████| 61/61 [00:16<00:00,  3.76batch/s]\n"
     ]
    },
    {
     "name": "stdout",
     "output_type": "stream",
     "text": [
      "Epoch Summary 8: Train Loss: 11.8132, Train Acc.: 0.5917, Val. Loss: 0.6863, Val. Acc.: 0.6876, Val. Precision: 0.6780, Val. Recall: 0.6501, Val. F1: 0.6548\n"
     ]
    },
    {
     "name": "stderr",
     "output_type": "stream",
     "text": [
      "Epoch 9: 100%|██████████| 223/223 [00:51<00:00,  4.36batch/s]\n",
      "Validation: 100%|██████████| 61/61 [00:16<00:00,  3.76batch/s]\n"
     ]
    },
    {
     "name": "stdout",
     "output_type": "stream",
     "text": [
      "Early Stopping: 1/10 without improvement.\n",
      "Epoch Summary 9: Train Loss: 11.6891, Train Acc.: 0.5976, Val. Loss: 0.6392, Val. Acc.: 0.6330, Val. Precision: 0.6250, Val. Recall: 0.7369, Val. F1: 0.6297\n"
     ]
    },
    {
     "name": "stderr",
     "output_type": "stream",
     "text": [
      "Epoch 10: 100%|██████████| 223/223 [00:51<00:00,  4.36batch/s]\n",
      "Validation: 100%|██████████| 61/61 [00:16<00:00,  3.77batch/s]\n"
     ]
    },
    {
     "name": "stdout",
     "output_type": "stream",
     "text": [
      "Early Stopping: 2/10 without improvement.\n",
      "Epoch Summary 10: Train Loss: 11.4537, Train Acc.: 0.6119, Val. Loss: 0.6839, Val. Acc.: 0.6794, Val. Precision: 0.6677, Val. Recall: 0.6682, Val. F1: 0.6599\n"
     ]
    },
    {
     "name": "stderr",
     "output_type": "stream",
     "text": [
      "Epoch 11: 100%|██████████| 223/223 [00:51<00:00,  4.35batch/s]\n",
      "Validation: 100%|██████████| 61/61 [00:16<00:00,  3.74batch/s]\n"
     ]
    },
    {
     "name": "stdout",
     "output_type": "stream",
     "text": [
      "Early Stopping: 3/10 without improvement.\n",
      "Epoch Summary 11: Train Loss: 11.1447, Train Acc.: 0.6237, Val. Loss: 0.6332, Val. Acc.: 0.6680, Val. Precision: 0.6310, Val. Recall: 0.6993, Val. F1: 0.6539\n"
     ]
    },
    {
     "name": "stderr",
     "output_type": "stream",
     "text": [
      "Epoch 12: 100%|██████████| 223/223 [00:51<00:00,  4.35batch/s]\n",
      "Validation:   0%|          | 0/61 [00:00<?, ?batch/s]Exception ignored in: <function _MultiProcessingDataLoaderIter.__del__ at 0x7f6683c88040>\n",
      "Traceback (most recent call last):\n",
      "Exception ignored in: <function _MultiProcessingDataLoaderIter.__del__ at 0x7f6683c88040>  File \"/usr/local/lib/python3.9/dist-packages/torch/utils/data/dataloader.py\", line 1604, in __del__\n",
      "    self._shutdown_workers()\n",
      "  File \"/usr/local/lib/python3.9/dist-packages/torch/utils/data/dataloader.py\", line 1587, in _shutdown_workers\n",
      "\n",
      "Exception ignored in: <function _MultiProcessingDataLoaderIter.__del__ at 0x7f6683c88040>Traceback (most recent call last):\n",
      "\n",
      "    Traceback (most recent call last):\n",
      "if w.is_alive():  File \"/usr/local/lib/python3.9/dist-packages/torch/utils/data/dataloader.py\", line 1604, in __del__\n",
      "\n",
      "  File \"/usr/lib/python3.9/multiprocessing/process.py\", line 160, in is_alive\n",
      "        assert self._parent_pid == os.getpid(), 'can only test a child process'  File \"/usr/local/lib/python3.9/dist-packages/torch/utils/data/dataloader.py\", line 1604, in __del__\n",
      "    \n",
      "self._shutdown_workers()AssertionErrorself._shutdown_workers(): can only test a child process\n",
      "\n",
      "  File \"/usr/local/lib/python3.9/dist-packages/torch/utils/data/dataloader.py\", line 1587, in _shutdown_workers\n",
      "    if w.is_alive():\n",
      "Exception ignored in:   File \"/usr/local/lib/python3.9/dist-packages/torch/utils/data/dataloader.py\", line 1587, in _shutdown_workers\n",
      "    \n",
      "  File \"/usr/lib/python3.9/multiprocessing/process.py\", line 160, in is_alive\n",
      "<function _MultiProcessingDataLoaderIter.__del__ at 0x7f6683c88040>\n",
      "if w.is_alive():\n",
      "Traceback (most recent call last):\n",
      "      File \"/usr/local/lib/python3.9/dist-packages/torch/utils/data/dataloader.py\", line 1604, in __del__\n",
      "  File \"/usr/lib/python3.9/multiprocessing/process.py\", line 160, in is_alive\n",
      "assert self._parent_pid == os.getpid(), 'can only test a child process'    \n",
      "Exception ignored in: <function _MultiProcessingDataLoaderIter.__del__ at 0x7f6683c88040>\n",
      "self._shutdown_workers()    AssertionErrorassert self._parent_pid == os.getpid(), 'can only test a child process'\n",
      "Traceback (most recent call last):\n",
      "\n",
      "  File \"/usr/local/lib/python3.9/dist-packages/torch/utils/data/dataloader.py\", line 1587, in _shutdown_workers\n",
      ":     if w.is_alive():AssertionError\n",
      "  File \"/usr/lib/python3.9/multiprocessing/process.py\", line 160, in is_alive\n",
      "can only test a child process\n",
      "    assert self._parent_pid == os.getpid(), 'can only test a child process'\n",
      ": can only test a child process\n",
      "AssertionErrorException ignored in:   File \"/usr/local/lib/python3.9/dist-packages/torch/utils/data/dataloader.py\", line 1604, in __del__\n",
      ":     <function _MultiProcessingDataLoaderIter.__del__ at 0x7f6683c88040>can only test a child process\n",
      "Traceback (most recent call last):\n",
      "self._shutdown_workers()\n",
      "  File \"/usr/local/lib/python3.9/dist-packages/torch/utils/data/dataloader.py\", line 1587, in _shutdown_workers\n",
      "\n",
      "  File \"/usr/local/lib/python3.9/dist-packages/torch/utils/data/dataloader.py\", line 1604, in __del__\n",
      "    if w.is_alive():    \n",
      "self._shutdown_workers()\n",
      "  File \"/usr/local/lib/python3.9/dist-packages/torch/utils/data/dataloader.py\", line 1587, in _shutdown_workers\n",
      "    if w.is_alive():\n",
      "  File \"/usr/lib/python3.9/multiprocessing/process.py\", line 160, in is_alive\n",
      "      File \"/usr/lib/python3.9/multiprocessing/process.py\", line 160, in is_alive\n",
      "    assert self._parent_pid == os.getpid(), 'can only test a child process'assert self._parent_pid == os.getpid(), 'can only test a child process'\n",
      "\n",
      "AssertionError: AssertionErrorException ignored in: can only test a child process\n",
      ": <function _MultiProcessingDataLoaderIter.__del__ at 0x7f6683c88040>can only test a child process\n",
      "Exception ignored in: \n",
      "<function _MultiProcessingDataLoaderIter.__del__ at 0x7f6683c88040>Exception ignored in: \n",
      "Traceback (most recent call last):\n",
      "<function _MultiProcessingDataLoaderIter.__del__ at 0x7f6683c88040>  File \"/usr/local/lib/python3.9/dist-packages/torch/utils/data/dataloader.py\", line 1604, in __del__\n",
      "Exception ignored in: Traceback (most recent call last):\n",
      "    \n",
      "<function _MultiProcessingDataLoaderIter.__del__ at 0x7f6683c88040>self._shutdown_workers()Traceback (most recent call last):\n",
      "  File \"/usr/local/lib/python3.9/dist-packages/torch/utils/data/dataloader.py\", line 1604, in __del__\n",
      "  File \"/usr/local/lib/python3.9/dist-packages/torch/utils/data/dataloader.py\", line 1604, in __del__\n",
      "    self._shutdown_workers()  File \"/usr/local/lib/python3.9/dist-packages/torch/utils/data/dataloader.py\", line 1587, in _shutdown_workers\n",
      "\n",
      "        self._shutdown_workers()\n",
      "  File \"/usr/local/lib/python3.9/dist-packages/torch/utils/data/dataloader.py\", line 1587, in _shutdown_workers\n",
      "    if w.is_alive():\n",
      "if w.is_alive():  File \"/usr/lib/python3.9/multiprocessing/process.py\", line 160, in is_alive\n",
      "\n",
      "\n",
      "\n",
      "  File \"/usr/local/lib/python3.9/dist-packages/torch/utils/data/dataloader.py\", line 1587, in _shutdown_workers\n",
      "    assert self._parent_pid == os.getpid(), 'can only test a child process'  File \"/usr/lib/python3.9/multiprocessing/process.py\", line 160, in is_alive\n",
      "Traceback (most recent call last):\n",
      "  File \"/usr/local/lib/python3.9/dist-packages/torch/utils/data/dataloader.py\", line 1604, in __del__\n",
      "              File \"/usr/lib/python3.9/multiprocessing/process.py\", line 160, in is_alive\n",
      "    if w.is_alive():assert self._parent_pid == os.getpid(), 'can only test a child process'\n",
      "\n",
      "\n",
      "AssertionErrorassert self._parent_pid == os.getpid(), 'can only test a child process': can only test a child processAssertionError: \n",
      "can only test a child processException ignored in: <function _MultiProcessingDataLoaderIter.__del__ at 0x7f6683c88040>self._shutdown_workers()\n",
      "\n",
      "AssertionError: \n",
      "Traceback (most recent call last):\n",
      "Exception ignored in:   File \"/usr/local/lib/python3.9/dist-packages/torch/utils/data/dataloader.py\", line 1587, in _shutdown_workers\n",
      "\n",
      "<function _MultiProcessingDataLoaderIter.__del__ at 0x7f6683c88040>can only test a child process\n",
      "  File \"/usr/local/lib/python3.9/dist-packages/torch/utils/data/dataloader.py\", line 1604, in __del__\n",
      "    \n",
      "    Traceback (most recent call last):\n",
      "if w.is_alive():\n",
      "self._shutdown_workers()  File \"/usr/lib/python3.9/multiprocessing/process.py\", line 160, in is_alive\n",
      "\n",
      "    assert self._parent_pid == os.getpid(), 'can only test a child process'  File \"/usr/local/lib/python3.9/dist-packages/torch/utils/data/dataloader.py\", line 1604, in __del__\n",
      "  File \"/usr/local/lib/python3.9/dist-packages/torch/utils/data/dataloader.py\", line 1587, in _shutdown_workers\n",
      "\n",
      "AssertionError: can only test a child process        self._shutdown_workers()if w.is_alive():\n",
      "\n",
      "\n",
      "  File \"/usr/local/lib/python3.9/dist-packages/torch/utils/data/dataloader.py\", line 1587, in _shutdown_workers\n",
      "  File \"/usr/lib/python3.9/multiprocessing/process.py\", line 160, in is_alive\n",
      "        assert self._parent_pid == os.getpid(), 'can only test a child process'\n",
      "AssertionError: can only test a child process\n",
      "if w.is_alive():\n",
      "  File \"/usr/lib/python3.9/multiprocessing/process.py\", line 160, in is_alive\n",
      "    Exception ignored in: assert self._parent_pid == os.getpid(), 'can only test a child process'<function _MultiProcessingDataLoaderIter.__del__ at 0x7f6683c88040>Exception ignored in: <function _MultiProcessingDataLoaderIter.__del__ at 0x7f6683c88040>\n",
      "Exception ignored in: Traceback (most recent call last):\n",
      "<function _MultiProcessingDataLoaderIter.__del__ at 0x7f6683c88040>  File \"/usr/local/lib/python3.9/dist-packages/torch/utils/data/dataloader.py\", line 1604, in __del__\n",
      "    self._shutdown_workers()\n",
      "  File \"/usr/local/lib/python3.9/dist-packages/torch/utils/data/dataloader.py\", line 1587, in _shutdown_workers\n",
      "\n",
      "    AssertionErrorif w.is_alive():: \n",
      "  File \"/usr/lib/python3.9/multiprocessing/process.py\", line 160, in is_alive\n",
      "    can only test a child process\n",
      "assert self._parent_pid == os.getpid(), 'can only test a child process'\n",
      "Exception ignored in: Traceback (most recent call last):\n",
      "\n",
      "  File \"/usr/local/lib/python3.9/dist-packages/torch/utils/data/dataloader.py\", line 1604, in __del__\n",
      "Exception ignored in: <function _MultiProcessingDataLoaderIter.__del__ at 0x7f6683c88040>\n",
      "AssertionError\n",
      "    : Traceback (most recent call last):\n",
      "<function _MultiProcessingDataLoaderIter.__del__ at 0x7f6683c88040>self._shutdown_workers()Traceback (most recent call last):\n",
      "  File \"/usr/local/lib/python3.9/dist-packages/torch/utils/data/dataloader.py\", line 1604, in __del__\n",
      "  File \"/usr/local/lib/python3.9/dist-packages/torch/utils/data/dataloader.py\", line 1604, in __del__\n",
      "        \n",
      "can only test a child process\n",
      "self._shutdown_workers()\n",
      "  File \"/usr/local/lib/python3.9/dist-packages/torch/utils/data/dataloader.py\", line 1587, in _shutdown_workers\n",
      "Traceback (most recent call last):\n",
      "self._shutdown_workers()\n",
      "  File \"/usr/local/lib/python3.9/dist-packages/torch/utils/data/dataloader.py\", line 1604, in __del__\n",
      "    \n",
      "  File \"/usr/local/lib/python3.9/dist-packages/torch/utils/data/dataloader.py\", line 1587, in _shutdown_workers\n",
      "  File \"/usr/local/lib/python3.9/dist-packages/torch/utils/data/dataloader.py\", line 1587, in _shutdown_workers\n",
      "        if w.is_alive():self._shutdown_workers()    \n",
      "\n",
      "if w.is_alive():  File \"/usr/lib/python3.9/multiprocessing/process.py\", line 160, in is_alive\n",
      "if w.is_alive():\n",
      "    assert self._parent_pid == os.getpid(), 'can only test a child process'  File \"/usr/lib/python3.9/multiprocessing/process.py\", line 160, in is_alive\n",
      "\n",
      "    assert self._parent_pid == os.getpid(), 'can only test a child process'  File \"/usr/lib/python3.9/multiprocessing/process.py\", line 160, in is_alive\n",
      "      File \"/usr/local/lib/python3.9/dist-packages/torch/utils/data/dataloader.py\", line 1587, in _shutdown_workers\n",
      "assert self._parent_pid == os.getpid(), 'can only test a child process'\n",
      "\n",
      "AssertionError    if w.is_alive():: \n",
      "AssertionErrorcan only test a child process\n",
      "  File \"/usr/lib/python3.9/multiprocessing/process.py\", line 160, in is_alive\n",
      ": can only test a child process    \n",
      "\n",
      "AssertionError: assert self._parent_pid == os.getpid(), 'can only test a child process'\n",
      "AssertionError: can only test a child process\n",
      "Exception ignored in: Exception ignored in: <function _MultiProcessingDataLoaderIter.__del__ at 0x7f6683c88040><function _MultiProcessingDataLoaderIter.__del__ at 0x7f6683c88040>can only test a child process\n",
      "\n",
      "Traceback (most recent call last):\n",
      "\n",
      "Traceback (most recent call last):\n",
      "  File \"/usr/local/lib/python3.9/dist-packages/torch/utils/data/dataloader.py\", line 1604, in __del__\n",
      "Exception ignored in:   File \"/usr/local/lib/python3.9/dist-packages/torch/utils/data/dataloader.py\", line 1604, in __del__\n",
      "    <function _MultiProcessingDataLoaderIter.__del__ at 0x7f6683c88040>    self._shutdown_workers()\n",
      "self._shutdown_workers()\n",
      "Traceback (most recent call last):\n",
      "\n",
      "  File \"/usr/local/lib/python3.9/dist-packages/torch/utils/data/dataloader.py\", line 1604, in __del__\n",
      "  File \"/usr/local/lib/python3.9/dist-packages/torch/utils/data/dataloader.py\", line 1587, in _shutdown_workers\n",
      "  File \"/usr/local/lib/python3.9/dist-packages/torch/utils/data/dataloader.py\", line 1587, in _shutdown_workers\n",
      "            if w.is_alive():self._shutdown_workers()Exception ignored in: Exception ignored in: \n",
      "if w.is_alive():<function _MultiProcessingDataLoaderIter.__del__ at 0x7f6683c88040>\n",
      "<function _MultiProcessingDataLoaderIter.__del__ at 0x7f6683c88040>  File \"/usr/local/lib/python3.9/dist-packages/torch/utils/data/dataloader.py\", line 1587, in _shutdown_workers\n",
      "  File \"/usr/lib/python3.9/multiprocessing/process.py\", line 160, in is_alive\n",
      "\n",
      "\n",
      "\n",
      "  File \"/usr/lib/python3.9/multiprocessing/process.py\", line 160, in is_alive\n",
      "Traceback (most recent call last):\n",
      "    Traceback (most recent call last):\n",
      "      File \"/usr/local/lib/python3.9/dist-packages/torch/utils/data/dataloader.py\", line 1604, in __del__\n",
      "assert self._parent_pid == os.getpid(), 'can only test a child process'  File \"/usr/local/lib/python3.9/dist-packages/torch/utils/data/dataloader.py\", line 1604, in __del__\n",
      "assert self._parent_pid == os.getpid(), 'can only test a child process'\n",
      "\n",
      "    AssertionErrorself._shutdown_workers()    AssertionError: self._shutdown_workers()\n",
      "can only test a child processException ignored in: :   File \"/usr/local/lib/python3.9/dist-packages/torch/utils/data/dataloader.py\", line 1587, in _shutdown_workers\n",
      "<function _MultiProcessingDataLoaderIter.__del__ at 0x7f6683c88040>can only test a child process\n",
      "\n",
      "    \n",
      "    if w.is_alive():\n",
      "\n",
      "  File \"/usr/lib/python3.9/multiprocessing/process.py\", line 160, in is_alive\n",
      "  File \"/usr/local/lib/python3.9/dist-packages/torch/utils/data/dataloader.py\", line 1587, in _shutdown_workers\n",
      "    if w.is_alive():Traceback (most recent call last):\n",
      "  File \"/usr/local/lib/python3.9/dist-packages/torch/utils/data/dataloader.py\", line 1604, in __del__\n",
      "    if w.is_alive():self._shutdown_workers()\n",
      "  File \"/usr/lib/python3.9/multiprocessing/process.py\", line 160, in is_alive\n",
      "        assert self._parent_pid == os.getpid(), 'can only test a child process'\n",
      "assert self._parent_pid == os.getpid(), 'can only test a child process'\n",
      "\n",
      "  File \"/usr/lib/python3.9/multiprocessing/process.py\", line 160, in is_alive\n",
      "\n",
      "\n",
      "  File \"/usr/local/lib/python3.9/dist-packages/torch/utils/data/dataloader.py\", line 1587, in _shutdown_workers\n",
      "AssertionError    \n",
      "    AssertionError: : can only test a child processif w.is_alive():can only test a child process\n",
      "assert self._parent_pid == os.getpid(), 'can only test a child process'  File \"/usr/lib/python3.9/multiprocessing/process.py\", line 160, in is_alive\n",
      "    \n",
      "Exception ignored in: <function _MultiProcessingDataLoaderIter.__del__ at 0x7f6683c88040>assert self._parent_pid == os.getpid(), 'can only test a child process'\n",
      "\n",
      "Traceback (most recent call last):\n",
      "AssertionErrorAssertionError  File \"/usr/local/lib/python3.9/dist-packages/torch/utils/data/dataloader.py\", line 1604, in __del__\n",
      ":     : self._shutdown_workers()\n",
      "  File \"/usr/local/lib/python3.9/dist-packages/torch/utils/data/dataloader.py\", line 1587, in _shutdown_workers\n",
      "    can only test a child processif w.is_alive():\n",
      "\n",
      "can only test a child process  File \"/usr/lib/python3.9/multiprocessing/process.py\", line 160, in is_alive\n",
      "    \n",
      "assert self._parent_pid == os.getpid(), 'can only test a child process'Exception ignored in: \n",
      "AssertionError<function _MultiProcessingDataLoaderIter.__del__ at 0x7f6683c88040>Exception ignored in: <function _MultiProcessingDataLoaderIter.__del__ at 0x7f6683c88040>: \n",
      "can only test a child processTraceback (most recent call last):\n",
      "\n",
      "Traceback (most recent call last):\n",
      "  File \"/usr/local/lib/python3.9/dist-packages/torch/utils/data/dataloader.py\", line 1604, in __del__\n",
      "    self._shutdown_workers()  File \"/usr/local/lib/python3.9/dist-packages/torch/utils/data/dataloader.py\", line 1604, in __del__\n",
      "\n",
      "\n",
      "  File \"/usr/local/lib/python3.9/dist-packages/torch/utils/data/dataloader.py\", line 1587, in _shutdown_workers\n",
      "Exception ignored in:     Exception ignored in: if w.is_alive():    <function _MultiProcessingDataLoaderIter.__del__ at 0x7f6683c88040>\n",
      "\n",
      "<function _MultiProcessingDataLoaderIter.__del__ at 0x7f6683c88040>Traceback (most recent call last):\n",
      "  File \"/usr/lib/python3.9/multiprocessing/process.py\", line 160, in is_alive\n",
      "\n",
      "      File \"/usr/local/lib/python3.9/dist-packages/torch/utils/data/dataloader.py\", line 1604, in __del__\n",
      "    Traceback (most recent call last):\n",
      "self._shutdown_workers()assert self._parent_pid == os.getpid(), 'can only test a child process'self._shutdown_workers()  File \"/usr/local/lib/python3.9/dist-packages/torch/utils/data/dataloader.py\", line 1604, in __del__\n",
      "\n",
      "    self._shutdown_workers()AssertionError\n",
      ":   File \"/usr/local/lib/python3.9/dist-packages/torch/utils/data/dataloader.py\", line 1587, in _shutdown_workers\n",
      "can only test a child process\n",
      "    \n",
      "  File \"/usr/local/lib/python3.9/dist-packages/torch/utils/data/dataloader.py\", line 1587, in _shutdown_workers\n",
      "    if w.is_alive():if w.is_alive():\n",
      "  File \"/usr/local/lib/python3.9/dist-packages/torch/utils/data/dataloader.py\", line 1587, in _shutdown_workers\n",
      "    \n",
      "\n",
      "if w.is_alive():  File \"/usr/lib/python3.9/multiprocessing/process.py\", line 160, in is_alive\n",
      "  File \"/usr/lib/python3.9/multiprocessing/process.py\", line 160, in is_alive\n",
      "        assert self._parent_pid == os.getpid(), 'can only test a child process'assert self._parent_pid == os.getpid(), 'can only test a child process'\n",
      "\n",
      "AssertionError: AssertionError: can only test a child processcan only test a child process\n",
      "Exception ignored in: \n",
      "  File \"/usr/lib/python3.9/multiprocessing/process.py\", line 160, in is_alive\n",
      "<function _MultiProcessingDataLoaderIter.__del__ at 0x7f6683c88040>    assert self._parent_pid == os.getpid(), 'can only test a child process'\n",
      "Exception ignored in: \n",
      "<function _MultiProcessingDataLoaderIter.__del__ at 0x7f6683c88040>Traceback (most recent call last):\n",
      "\n",
      "\n",
      "Exception ignored in: <function _MultiProcessingDataLoaderIter.__del__ at 0x7f6683c88040>  File \"/usr/local/lib/python3.9/dist-packages/torch/utils/data/dataloader.py\", line 1604, in __del__\n",
      "Traceback (most recent call last):\n",
      "  File \"/usr/local/lib/python3.9/dist-packages/torch/utils/data/dataloader.py\", line 1604, in __del__\n",
      "    \n",
      "AssertionError: can only test a child processTraceback (most recent call last):\n",
      "  File \"/usr/local/lib/python3.9/dist-packages/torch/utils/data/dataloader.py\", line 1604, in __del__\n",
      "    \n",
      "self._shutdown_workers()self._shutdown_workers()\n",
      "Exception ignored in: \n",
      "  File \"/usr/local/lib/python3.9/dist-packages/torch/utils/data/dataloader.py\", line 1587, in _shutdown_workers\n",
      "    self._shutdown_workers()  File \"/usr/local/lib/python3.9/dist-packages/torch/utils/data/dataloader.py\", line 1587, in _shutdown_workers\n",
      "    if w.is_alive():\n",
      "\n",
      "<function _MultiProcessingDataLoaderIter.__del__ at 0x7f6683c88040>  File \"/usr/lib/python3.9/multiprocessing/process.py\", line 160, in is_alive\n",
      "      File \"/usr/local/lib/python3.9/dist-packages/torch/utils/data/dataloader.py\", line 1587, in _shutdown_workers\n",
      "if w.is_alive():    assert self._parent_pid == os.getpid(), 'can only test a child process'    \n",
      "\n",
      "AssertionError: can only test a child process  File \"/usr/lib/python3.9/multiprocessing/process.py\", line 160, in is_alive\n",
      "    assert self._parent_pid == os.getpid(), 'can only test a child process'\n",
      "AssertionErrorif w.is_alive():: \n",
      "\n",
      "can only test a child process  File \"/usr/lib/python3.9/multiprocessing/process.py\", line 160, in is_alive\n",
      "\n",
      "\n",
      "    assert self._parent_pid == os.getpid(), 'can only test a child process'Traceback (most recent call last):\n",
      "\n",
      "AssertionErrorException ignored in: : Exception ignored in:   File \"/usr/local/lib/python3.9/dist-packages/torch/utils/data/dataloader.py\", line 1604, in __del__\n",
      "    self._shutdown_workers()\n",
      "<function _MultiProcessingDataLoaderIter.__del__ at 0x7f6683c88040>can only test a child process\n",
      "<function _MultiProcessingDataLoaderIter.__del__ at 0x7f6683c88040>\n",
      "\n",
      "Traceback (most recent call last):\n",
      "  File \"/usr/local/lib/python3.9/dist-packages/torch/utils/data/dataloader.py\", line 1604, in __del__\n",
      "Traceback (most recent call last):\n",
      "  File \"/usr/local/lib/python3.9/dist-packages/torch/utils/data/dataloader.py\", line 1587, in _shutdown_workers\n",
      "  File \"/usr/local/lib/python3.9/dist-packages/torch/utils/data/dataloader.py\", line 1604, in __del__\n",
      "    Traceback (most recent call last):\n",
      "  File \"/usr/lib/python3.9/multiprocessing/queues.py\", line 241, in _feed\n",
      "    close()\n",
      "  File \"/usr/lib/python3.9/multiprocessing/connection.py\", line 182, in close\n",
      "    self._close()\n",
      "  File \"/usr/lib/python3.9/multiprocessing/connection.py\", line 366, in _close\n",
      "    _close(self._handle)\n",
      "OSError: [Errno 9] Bad file descriptor\n",
      "Traceback (most recent call last):\n",
      "  File \"/usr/lib/python3.9/multiprocessing/queues.py\", line 241, in _feed\n",
      "    close()\n",
      "  File \"/usr/lib/python3.9/multiprocessing/connection.py\", line 182, in close\n",
      "    self._close()\n",
      "  File \"/usr/lib/python3.9/multiprocessing/connection.py\", line 366, in _close\n",
      "    _close(self._handle)\n",
      "OSError: [Errno 9] Bad file descriptor\n",
      "Traceback (most recent call last):\n",
      "  File \"/usr/lib/python3.9/multiprocessing/queues.py\", line 241, in _feed\n",
      "    close()\n",
      "  File \"/usr/lib/python3.9/multiprocessing/connection.py\", line 182, in close\n",
      "    self._close()\n",
      "  File \"/usr/lib/python3.9/multiprocessing/connection.py\", line 366, in _close\n",
      "    _close(self._handle)\n",
      "OSError: [Errno 9] Bad file descriptor\n",
      "Traceback (most recent call last):\n",
      "  File \"/usr/lib/python3.9/multiprocessing/queues.py\", line 241, in _feed\n",
      "    close()\n",
      "  File \"/usr/lib/python3.9/multiprocessing/connection.py\", line 182, in close\n",
      "    self._close()\n",
      "  File \"/usr/lib/python3.9/multiprocessing/connection.py\", line 366, in _close\n",
      "    _close(self._handle)\n",
      "OSError: [Errno 9] Bad file descriptor\n",
      "Traceback (most recent call last):\n",
      "  File \"/usr/lib/python3.9/multiprocessing/queues.py\", line 241, in _feed\n",
      "    close()\n",
      "  File \"/usr/lib/python3.9/multiprocessing/connection.py\", line 182, in close\n",
      "    self._close()\n",
      "  File \"/usr/lib/python3.9/multiprocessing/connection.py\", line 366, in _close\n",
      "    _close(self._handle)\n",
      "OSError: [Errno 9] Bad file descriptor\n",
      "Traceback (most recent call last):\n",
      "  File \"/usr/lib/python3.9/multiprocessing/queues.py\", line 241, in _feed\n",
      "    close()\n",
      "  File \"/usr/lib/python3.9/multiprocessing/connection.py\", line 182, in close\n",
      "    self._close()\n",
      "  File \"/usr/lib/python3.9/multiprocessing/connection.py\", line 366, in _close\n",
      "    _close(self._handle)\n",
      "OSError: [Errno 9] Bad file descriptor\n",
      "Traceback (most recent call last):\n",
      "  File \"/usr/lib/python3.9/multiprocessing/queues.py\", line 241, in _feed\n",
      "    close()\n",
      "  File \"/usr/lib/python3.9/multiprocessing/connection.py\", line 182, in close\n",
      "    self._close()\n",
      "  File \"/usr/lib/python3.9/multiprocessing/connection.py\", line 366, in _close\n",
      "    _close(self._handle)\n",
      "OSError: [Errno 9] Bad file descriptor\n",
      "Traceback (most recent call last):\n",
      "  File \"/usr/lib/python3.9/multiprocessing/queues.py\", line 241, in _feed\n",
      "    close()\n",
      "  File \"/usr/lib/python3.9/multiprocessing/connection.py\", line 182, in close\n",
      "    self._close()\n",
      "  File \"/usr/lib/python3.9/multiprocessing/connection.py\", line 366, in _close\n",
      "    _close(self._handle)\n",
      "OSError: [Errno 9] Bad file descriptor\n",
      "    Exception ignored in:     self._shutdown_workers()if w.is_alive():\n",
      "\n",
      "  File \"/usr/local/lib/python3.9/dist-packages/torch/utils/data/dataloader.py\", line 1587, in _shutdown_workers\n",
      "  File \"/usr/lib/python3.9/multiprocessing/process.py\", line 160, in is_alive\n",
      "    <function _MultiProcessingDataLoaderIter.__del__ at 0x7f6683c88040>\n",
      "Traceback (most recent call last):\n",
      "  File \"/usr/local/lib/python3.9/dist-packages/torch/utils/data/dataloader.py\", line 1604, in __del__\n",
      "    self._shutdown_workers()    \n",
      "if w.is_alive():  File \"/usr/local/lib/python3.9/dist-packages/torch/utils/data/dataloader.py\", line 1587, in _shutdown_workers\n",
      "self._shutdown_workers()\n",
      "      File \"/usr/local/lib/python3.9/dist-packages/torch/utils/data/dataloader.py\", line 1587, in _shutdown_workers\n",
      "if w.is_alive():assert self._parent_pid == os.getpid(), 'can only test a child process'\n",
      "\n",
      "  File \"/usr/lib/python3.9/multiprocessing/process.py\", line 160, in is_alive\n",
      "AssertionError    : assert self._parent_pid == os.getpid(), 'can only test a child process'can only test a child process\n",
      "\n",
      "AssertionError\n",
      "    : if w.is_alive():  File \"/usr/lib/python3.9/multiprocessing/process.py\", line 160, in is_alive\n",
      "\n",
      "    can only test a child processassert self._parent_pid == os.getpid(), 'can only test a child process'\n",
      "  File \"/usr/lib/python3.9/multiprocessing/process.py\", line 160, in is_alive\n",
      ": \n",
      "AssertionErrorcan only test a child process\n",
      "    Exception ignored in: assert self._parent_pid == os.getpid(), 'can only test a child process'<function _MultiProcessingDataLoaderIter.__del__ at 0x7f6683c88040>\n",
      "AssertionError\n",
      "Traceback (most recent call last):\n",
      ": can only test a child process  File \"/usr/local/lib/python3.9/dist-packages/torch/utils/data/dataloader.py\", line 1604, in __del__\n",
      "    self._shutdown_workers()\n",
      "  File \"/usr/local/lib/python3.9/dist-packages/torch/utils/data/dataloader.py\", line 1587, in _shutdown_workers\n",
      "    if w.is_alive():\n",
      "  File \"/usr/lib/python3.9/multiprocessing/process.py\", line 160, in is_alive\n",
      "    assert self._parent_pid == os.getpid(), 'can only test a child process'\n",
      "AssertionError: can only test a child process\n",
      "\n",
      "Traceback (most recent call last):\n",
      "Traceback (most recent call last):\n",
      "Traceback (most recent call last):\n",
      "Traceback (most recent call last):\n",
      "Traceback (most recent call last):\n",
      "Traceback (most recent call last):\n",
      "Traceback (most recent call last):\n",
      "Traceback (most recent call last):\n",
      "Traceback (most recent call last):\n",
      "Traceback (most recent call last):\n",
      "Traceback (most recent call last):\n",
      "Traceback (most recent call last):\n",
      "Traceback (most recent call last):\n",
      "Traceback (most recent call last):\n",
      "Traceback (most recent call last):\n",
      "Traceback (most recent call last):\n",
      "Traceback (most recent call last):\n",
      "Traceback (most recent call last):\n",
      "Traceback (most recent call last):\n",
      "Traceback (most recent call last):\n",
      "Traceback (most recent call last):\n",
      "Traceback (most recent call last):\n",
      "Traceback (most recent call last):\n",
      "Traceback (most recent call last):\n",
      "Traceback (most recent call last):\n",
      "Traceback (most recent call last):\n",
      "Traceback (most recent call last):\n",
      "Traceback (most recent call last):\n",
      "Traceback (most recent call last):\n",
      "Traceback (most recent call last):\n",
      "Traceback (most recent call last):\n",
      "Traceback (most recent call last):\n",
      "Traceback (most recent call last):\n",
      "Traceback (most recent call last):\n",
      "Traceback (most recent call last):\n",
      "Traceback (most recent call last):\n",
      "Traceback (most recent call last):\n",
      "Traceback (most recent call last):\n",
      "Traceback (most recent call last):\n",
      "Traceback (most recent call last):\n",
      "Traceback (most recent call last):\n",
      "Traceback (most recent call last):\n",
      "Traceback (most recent call last):\n",
      "Traceback (most recent call last):\n",
      "Traceback (most recent call last):\n",
      "Traceback (most recent call last):\n",
      "Traceback (most recent call last):\n",
      "Traceback (most recent call last):\n",
      "Traceback (most recent call last):\n",
      "Traceback (most recent call last):\n",
      "Traceback (most recent call last):\n",
      "Traceback (most recent call last):\n",
      "Traceback (most recent call last):\n",
      "Traceback (most recent call last):\n",
      "Traceback (most recent call last):\n",
      "Traceback (most recent call last):\n",
      "Traceback (most recent call last):\n",
      "Traceback (most recent call last):\n",
      "Traceback (most recent call last):\n",
      "Traceback (most recent call last):\n",
      "Traceback (most recent call last):\n",
      "Traceback (most recent call last):\n",
      "Traceback (most recent call last):\n",
      "Traceback (most recent call last):\n",
      "Traceback (most recent call last):\n",
      "Traceback (most recent call last):\n",
      "Traceback (most recent call last):\n",
      "Traceback (most recent call last):\n",
      "Traceback (most recent call last):\n",
      "Traceback (most recent call last):\n",
      "Traceback (most recent call last):\n",
      "Traceback (most recent call last):\n",
      "Traceback (most recent call last):\n",
      "Traceback (most recent call last):\n",
      "Traceback (most recent call last):\n",
      "Traceback (most recent call last):\n",
      "Traceback (most recent call last):\n",
      "Traceback (most recent call last):\n",
      "  File \"/usr/lib/python3.9/multiprocessing/queues.py\", line 241, in _feed\n",
      "    close()\n",
      "  File \"/usr/lib/python3.9/multiprocessing/queues.py\", line 241, in _feed\n",
      "    close()\n",
      "  File \"/usr/lib/python3.9/multiprocessing/queues.py\", line 241, in _feed\n",
      "    close()\n",
      "  File \"/usr/lib/python3.9/multiprocessing/queues.py\", line 241, in _feed\n",
      "    close()\n",
      "  File \"/usr/lib/python3.9/multiprocessing/queues.py\", line 241, in _feed\n",
      "    close()\n",
      "  File \"/usr/lib/python3.9/multiprocessing/queues.py\", line 241, in _feed\n",
      "    close()\n",
      "  File \"/usr/lib/python3.9/multiprocessing/queues.py\", line 241, in _feed\n",
      "    close()\n",
      "  File \"/usr/lib/python3.9/multiprocessing/queues.py\", line 241, in _feed\n",
      "    close()\n",
      "  File \"/usr/lib/python3.9/multiprocessing/queues.py\", line 241, in _feed\n",
      "    close()\n",
      "  File \"/usr/lib/python3.9/multiprocessing/queues.py\", line 241, in _feed\n",
      "    close()\n",
      "  File \"/usr/lib/python3.9/multiprocessing/queues.py\", line 241, in _feed\n",
      "    close()\n",
      "  File \"/usr/lib/python3.9/multiprocessing/queues.py\", line 241, in _feed\n",
      "    close()\n",
      "  File \"/usr/lib/python3.9/multiprocessing/queues.py\", line 241, in _feed\n",
      "    close()\n",
      "  File \"/usr/lib/python3.9/multiprocessing/queues.py\", line 241, in _feed\n",
      "    close()\n",
      "  File \"/usr/lib/python3.9/multiprocessing/queues.py\", line 241, in _feed\n",
      "    close()\n",
      "  File \"/usr/lib/python3.9/multiprocessing/queues.py\", line 241, in _feed\n",
      "    close()\n",
      "  File \"/usr/lib/python3.9/multiprocessing/queues.py\", line 241, in _feed\n",
      "    close()\n",
      "  File \"/usr/lib/python3.9/multiprocessing/queues.py\", line 241, in _feed\n",
      "    close()\n",
      "Traceback (most recent call last):\n",
      "Traceback (most recent call last):\n",
      "  File \"/usr/lib/python3.9/multiprocessing/queues.py\", line 241, in _feed\n",
      "    close()\n",
      "  File \"/usr/lib/python3.9/multiprocessing/queues.py\", line 241, in _feed\n",
      "    close()\n",
      "  File \"/usr/lib/python3.9/multiprocessing/queues.py\", line 241, in _feed\n",
      "    close()\n",
      "  File \"/usr/lib/python3.9/multiprocessing/queues.py\", line 241, in _feed\n",
      "    close()\n",
      "  File \"/usr/lib/python3.9/multiprocessing/queues.py\", line 241, in _feed\n",
      "    close()\n",
      "  File \"/usr/lib/python3.9/multiprocessing/queues.py\", line 241, in _feed\n",
      "    close()\n",
      "  File \"/usr/lib/python3.9/multiprocessing/queues.py\", line 241, in _feed\n",
      "    close()\n",
      "  File \"/usr/lib/python3.9/multiprocessing/queues.py\", line 241, in _feed\n",
      "    close()\n",
      "  File \"/usr/lib/python3.9/multiprocessing/queues.py\", line 241, in _feed\n",
      "    close()\n",
      "  File \"/usr/lib/python3.9/multiprocessing/queues.py\", line 241, in _feed\n",
      "    close()\n",
      "  File \"/usr/lib/python3.9/multiprocessing/queues.py\", line 241, in _feed\n",
      "    close()\n",
      "  File \"/usr/lib/python3.9/multiprocessing/queues.py\", line 241, in _feed\n",
      "    close()\n",
      "  File \"/usr/lib/python3.9/multiprocessing/queues.py\", line 241, in _feed\n",
      "    close()\n",
      "  File \"/usr/lib/python3.9/multiprocessing/queues.py\", line 241, in _feed\n",
      "    close()\n",
      "  File \"/usr/lib/python3.9/multiprocessing/queues.py\", line 241, in _feed\n",
      "    close()\n",
      "  File \"/usr/lib/python3.9/multiprocessing/queues.py\", line 241, in _feed\n",
      "    close()\n",
      "  File \"/usr/lib/python3.9/multiprocessing/queues.py\", line 241, in _feed\n",
      "    close()\n",
      "  File \"/usr/lib/python3.9/multiprocessing/queues.py\", line 241, in _feed\n",
      "    close()\n",
      "  File \"/usr/lib/python3.9/multiprocessing/queues.py\", line 241, in _feed\n",
      "    close()\n",
      "  File \"/usr/lib/python3.9/multiprocessing/queues.py\", line 241, in _feed\n",
      "    close()\n",
      "  File \"/usr/lib/python3.9/multiprocessing/queues.py\", line 241, in _feed\n",
      "    close()\n",
      "  File \"/usr/lib/python3.9/multiprocessing/queues.py\", line 241, in _feed\n",
      "    close()\n",
      "  File \"/usr/lib/python3.9/multiprocessing/queues.py\", line 241, in _feed\n",
      "    close()\n",
      "  File \"/usr/lib/python3.9/multiprocessing/queues.py\", line 241, in _feed\n",
      "    close()\n",
      "  File \"/usr/lib/python3.9/multiprocessing/queues.py\", line 241, in _feed\n",
      "    close()\n",
      "  File \"/usr/lib/python3.9/multiprocessing/queues.py\", line 241, in _feed\n",
      "    close()\n",
      "  File \"/usr/lib/python3.9/multiprocessing/queues.py\", line 241, in _feed\n",
      "    close()\n",
      "  File \"/usr/lib/python3.9/multiprocessing/queues.py\", line 241, in _feed\n",
      "    close()\n",
      "  File \"/usr/lib/python3.9/multiprocessing/queues.py\", line 241, in _feed\n",
      "    close()\n",
      "  File \"/usr/lib/python3.9/multiprocessing/queues.py\", line 241, in _feed\n",
      "    close()\n",
      "  File \"/usr/lib/python3.9/multiprocessing/queues.py\", line 241, in _feed\n",
      "    close()\n",
      "  File \"/usr/lib/python3.9/multiprocessing/queues.py\", line 241, in _feed\n",
      "    close()\n",
      "  File \"/usr/lib/python3.9/multiprocessing/queues.py\", line 241, in _feed\n",
      "    close()\n",
      "  File \"/usr/lib/python3.9/multiprocessing/queues.py\", line 241, in _feed\n",
      "    close()\n",
      "  File \"/usr/lib/python3.9/multiprocessing/queues.py\", line 241, in _feed\n",
      "    close()\n",
      "  File \"/usr/lib/python3.9/multiprocessing/queues.py\", line 241, in _feed\n",
      "    close()\n",
      "  File \"/usr/lib/python3.9/multiprocessing/queues.py\", line 241, in _feed\n",
      "    close()\n",
      "  File \"/usr/lib/python3.9/multiprocessing/queues.py\", line 241, in _feed\n",
      "    close()\n",
      "  File \"/usr/lib/python3.9/multiprocessing/connection.py\", line 182, in close\n",
      "    self._close()\n",
      "  File \"/usr/lib/python3.9/multiprocessing/queues.py\", line 241, in _feed\n",
      "    close()\n",
      "  File \"/usr/lib/python3.9/multiprocessing/queues.py\", line 241, in _feed\n",
      "    close()\n",
      "  File \"/usr/lib/python3.9/multiprocessing/queues.py\", line 241, in _feed\n",
      "    close()\n",
      "  File \"/usr/lib/python3.9/multiprocessing/connection.py\", line 182, in close\n",
      "    self._close()\n",
      "  File \"/usr/lib/python3.9/multiprocessing/queues.py\", line 241, in _feed\n",
      "    close()\n",
      "  File \"/usr/lib/python3.9/multiprocessing/connection.py\", line 182, in close\n",
      "    self._close()\n",
      "  File \"/usr/lib/python3.9/multiprocessing/queues.py\", line 241, in _feed\n",
      "    close()\n",
      "  File \"/usr/lib/python3.9/multiprocessing/queues.py\", line 241, in _feed\n",
      "    close()\n",
      "  File \"/usr/lib/python3.9/multiprocessing/connection.py\", line 182, in close\n",
      "    self._close()\n",
      "  File \"/usr/lib/python3.9/multiprocessing/connection.py\", line 182, in close\n",
      "    self._close()\n",
      "  File \"/usr/lib/python3.9/multiprocessing/connection.py\", line 182, in close\n",
      "    self._close()\n",
      "  File \"/usr/lib/python3.9/multiprocessing/queues.py\", line 241, in _feed\n",
      "    close()\n",
      "  File \"/usr/lib/python3.9/multiprocessing/queues.py\", line 241, in _feed\n",
      "    close()\n",
      "  File \"/usr/lib/python3.9/multiprocessing/queues.py\", line 241, in _feed\n",
      "    close()\n",
      "  File \"/usr/lib/python3.9/multiprocessing/connection.py\", line 182, in close\n",
      "    self._close()\n",
      "  File \"/usr/lib/python3.9/multiprocessing/connection.py\", line 182, in close\n",
      "    self._close()\n",
      "  File \"/usr/lib/python3.9/multiprocessing/connection.py\", line 182, in close\n",
      "    self._close()\n",
      "  File \"/usr/lib/python3.9/multiprocessing/queues.py\", line 241, in _feed\n",
      "    close()\n",
      "  File \"/usr/lib/python3.9/multiprocessing/connection.py\", line 182, in close\n",
      "    self._close()\n",
      "  File \"/usr/lib/python3.9/multiprocessing/connection.py\", line 182, in close\n",
      "    self._close()\n",
      "  File \"/usr/lib/python3.9/multiprocessing/queues.py\", line 241, in _feed\n",
      "    close()\n",
      "  File \"/usr/lib/python3.9/multiprocessing/queues.py\", line 241, in _feed\n",
      "    close()\n",
      "  File \"/usr/lib/python3.9/multiprocessing/queues.py\", line 241, in _feed\n",
      "    close()\n",
      "  File \"/usr/lib/python3.9/multiprocessing/queues.py\", line 241, in _feed\n",
      "    close()\n",
      "  File \"/usr/lib/python3.9/multiprocessing/connection.py\", line 182, in close\n",
      "    self._close()\n",
      "  File \"/usr/lib/python3.9/multiprocessing/queues.py\", line 241, in _feed\n",
      "    close()\n",
      "  File \"/usr/lib/python3.9/multiprocessing/connection.py\", line 182, in close\n",
      "    self._close()\n",
      "  File \"/usr/lib/python3.9/multiprocessing/connection.py\", line 182, in close\n",
      "    self._close()\n",
      "  File \"/usr/lib/python3.9/multiprocessing/connection.py\", line 182, in close\n",
      "    self._close()\n",
      "  File \"/usr/lib/python3.9/multiprocessing/connection.py\", line 182, in close\n",
      "    self._close()\n",
      "  File \"/usr/lib/python3.9/multiprocessing/queues.py\", line 241, in _feed\n",
      "    close()\n",
      "  File \"/usr/lib/python3.9/multiprocessing/queues.py\", line 241, in _feed\n",
      "    close()\n",
      "  File \"/usr/lib/python3.9/multiprocessing/connection.py\", line 182, in close\n",
      "    self._close()\n",
      "  File \"/usr/lib/python3.9/multiprocessing/queues.py\", line 241, in _feed\n",
      "    close()\n",
      "  File \"/usr/lib/python3.9/multiprocessing/connection.py\", line 182, in close\n",
      "    self._close()\n",
      "  File \"/usr/lib/python3.9/multiprocessing/connection.py\", line 182, in close\n",
      "    self._close()\n",
      "  File \"/usr/lib/python3.9/multiprocessing/connection.py\", line 366, in _close\n",
      "    _close(self._handle)\n",
      "  File \"/usr/lib/python3.9/multiprocessing/queues.py\", line 241, in _feed\n",
      "    close()\n",
      "  File \"/usr/lib/python3.9/multiprocessing/connection.py\", line 182, in close\n",
      "    self._close()\n",
      "  File \"/usr/lib/python3.9/multiprocessing/queues.py\", line 241, in _feed\n",
      "    close()\n",
      "  File \"/usr/lib/python3.9/multiprocessing/queues.py\", line 241, in _feed\n",
      "    close()\n",
      "  File \"/usr/lib/python3.9/multiprocessing/connection.py\", line 182, in close\n",
      "    self._close()\n",
      "  File \"/usr/lib/python3.9/multiprocessing/connection.py\", line 182, in close\n",
      "    self._close()\n",
      "  File \"/usr/lib/python3.9/multiprocessing/connection.py\", line 182, in close\n",
      "    self._close()\n",
      "  File \"/usr/lib/python3.9/multiprocessing/connection.py\", line 182, in close\n",
      "    self._close()\n",
      "  File \"/usr/lib/python3.9/multiprocessing/connection.py\", line 182, in close\n",
      "    self._close()\n",
      "  File \"/usr/lib/python3.9/multiprocessing/connection.py\", line 182, in close\n",
      "    self._close()\n",
      "  File \"/usr/lib/python3.9/multiprocessing/connection.py\", line 182, in close\n",
      "    self._close()\n",
      "  File \"/usr/lib/python3.9/multiprocessing/connection.py\", line 182, in close\n",
      "    self._close()\n",
      "  File \"/usr/lib/python3.9/multiprocessing/connection.py\", line 182, in close\n",
      "    self._close()\n",
      "  File \"/usr/lib/python3.9/multiprocessing/connection.py\", line 182, in close\n",
      "    self._close()\n",
      "  File \"/usr/lib/python3.9/multiprocessing/connection.py\", line 182, in close\n",
      "    self._close()\n",
      "  File \"/usr/lib/python3.9/multiprocessing/connection.py\", line 182, in close\n",
      "    self._close()\n",
      "  File \"/usr/lib/python3.9/multiprocessing/connection.py\", line 182, in close\n",
      "    self._close()\n",
      "  File \"/usr/lib/python3.9/multiprocessing/connection.py\", line 182, in close\n",
      "    self._close()\n",
      "  File \"/usr/lib/python3.9/multiprocessing/connection.py\", line 182, in close\n",
      "    self._close()\n",
      "  File \"/usr/lib/python3.9/multiprocessing/connection.py\", line 182, in close\n",
      "    self._close()\n",
      "  File \"/usr/lib/python3.9/multiprocessing/queues.py\", line 241, in _feed\n",
      "    close()\n",
      "  File \"/usr/lib/python3.9/multiprocessing/connection.py\", line 182, in close\n",
      "    self._close()\n",
      "  File \"/usr/lib/python3.9/multiprocessing/connection.py\", line 182, in close\n",
      "    self._close()\n",
      "  File \"/usr/lib/python3.9/multiprocessing/connection.py\", line 182, in close\n",
      "    self._close()\n",
      "  File \"/usr/lib/python3.9/multiprocessing/connection.py\", line 182, in close\n",
      "    self._close()\n",
      "  File \"/usr/lib/python3.9/multiprocessing/connection.py\", line 182, in close\n",
      "    self._close()\n",
      "  File \"/usr/lib/python3.9/multiprocessing/connection.py\", line 182, in close\n",
      "    self._close()\n",
      "  File \"/usr/lib/python3.9/multiprocessing/connection.py\", line 182, in close\n",
      "    self._close()\n",
      "  File \"/usr/lib/python3.9/multiprocessing/queues.py\", line 241, in _feed\n",
      "    close()\n",
      "  File \"/usr/lib/python3.9/multiprocessing/connection.py\", line 182, in close\n",
      "    self._close()\n",
      "  File \"/usr/lib/python3.9/multiprocessing/connection.py\", line 182, in close\n",
      "    self._close()\n",
      "  File \"/usr/lib/python3.9/multiprocessing/connection.py\", line 182, in close\n",
      "    self._close()\n",
      "  File \"/usr/lib/python3.9/multiprocessing/connection.py\", line 182, in close\n",
      "    self._close()\n",
      "  File \"/usr/lib/python3.9/multiprocessing/connection.py\", line 182, in close\n",
      "    self._close()\n",
      "  File \"/usr/lib/python3.9/multiprocessing/queues.py\", line 241, in _feed\n",
      "    close()\n",
      "  File \"/usr/lib/python3.9/multiprocessing/connection.py\", line 182, in close\n",
      "    self._close()\n",
      "  File \"/usr/lib/python3.9/multiprocessing/connection.py\", line 182, in close\n",
      "    self._close()\n",
      "  File \"/usr/lib/python3.9/multiprocessing/connection.py\", line 182, in close\n",
      "    self._close()\n",
      "  File \"/usr/lib/python3.9/multiprocessing/connection.py\", line 182, in close\n",
      "    self._close()\n",
      "  File \"/usr/lib/python3.9/multiprocessing/connection.py\", line 182, in close\n",
      "    self._close()\n",
      "  File \"/usr/lib/python3.9/multiprocessing/connection.py\", line 182, in close\n",
      "    self._close()\n",
      "  File \"/usr/lib/python3.9/multiprocessing/connection.py\", line 182, in close\n",
      "    self._close()\n",
      "  File \"/usr/lib/python3.9/multiprocessing/connection.py\", line 182, in close\n",
      "    self._close()\n",
      "  File \"/usr/lib/python3.9/multiprocessing/connection.py\", line 182, in close\n",
      "    self._close()\n",
      "  File \"/usr/lib/python3.9/multiprocessing/connection.py\", line 366, in _close\n",
      "    _close(self._handle)\n",
      "  File \"/usr/lib/python3.9/multiprocessing/connection.py\", line 182, in close\n",
      "    self._close()\n",
      "  File \"/usr/lib/python3.9/multiprocessing/connection.py\", line 182, in close\n",
      "    self._close()\n",
      "  File \"/usr/lib/python3.9/multiprocessing/connection.py\", line 366, in _close\n",
      "    _close(self._handle)\n",
      "  File \"/usr/lib/python3.9/multiprocessing/connection.py\", line 182, in close\n",
      "    self._close()\n",
      "  File \"/usr/lib/python3.9/multiprocessing/connection.py\", line 366, in _close\n",
      "    _close(self._handle)\n",
      "  File \"/usr/lib/python3.9/multiprocessing/connection.py\", line 182, in close\n",
      "    self._close()\n",
      "  File \"/usr/lib/python3.9/multiprocessing/connection.py\", line 182, in close\n",
      "    self._close()\n",
      "  File \"/usr/lib/python3.9/multiprocessing/connection.py\", line 366, in _close\n",
      "    _close(self._handle)\n",
      "  File \"/usr/lib/python3.9/multiprocessing/connection.py\", line 182, in close\n",
      "    self._close()\n",
      "  File \"/usr/lib/python3.9/multiprocessing/connection.py\", line 182, in close\n",
      "    self._close()\n",
      "  File \"/usr/lib/python3.9/multiprocessing/connection.py\", line 182, in close\n",
      "    self._close()\n",
      "  File \"/usr/lib/python3.9/multiprocessing/connection.py\", line 366, in _close\n",
      "    _close(self._handle)\n",
      "  File \"/usr/lib/python3.9/multiprocessing/connection.py\", line 366, in _close\n",
      "    _close(self._handle)\n",
      "  File \"/usr/lib/python3.9/multiprocessing/connection.py\", line 182, in close\n",
      "    self._close()\n",
      "  File \"/usr/lib/python3.9/multiprocessing/connection.py\", line 366, in _close\n",
      "    _close(self._handle)\n",
      "  File \"/usr/lib/python3.9/multiprocessing/connection.py\", line 366, in _close\n",
      "    _close(self._handle)\n",
      "  File \"/usr/lib/python3.9/multiprocessing/connection.py\", line 366, in _close\n",
      "    _close(self._handle)\n",
      "  File \"/usr/lib/python3.9/multiprocessing/connection.py\", line 182, in close\n",
      "    self._close()\n",
      "  File \"/usr/lib/python3.9/multiprocessing/connection.py\", line 366, in _close\n",
      "    _close(self._handle)\n",
      "  File \"/usr/lib/python3.9/multiprocessing/connection.py\", line 182, in close\n",
      "    self._close()\n",
      "  File \"/usr/lib/python3.9/multiprocessing/connection.py\", line 182, in close\n",
      "    self._close()\n",
      "  File \"/usr/lib/python3.9/multiprocessing/connection.py\", line 366, in _close\n",
      "    _close(self._handle)\n",
      "  File \"/usr/lib/python3.9/multiprocessing/connection.py\", line 182, in close\n",
      "    self._close()\n",
      "  File \"/usr/lib/python3.9/multiprocessing/connection.py\", line 366, in _close\n",
      "    _close(self._handle)\n",
      "  File \"/usr/lib/python3.9/multiprocessing/connection.py\", line 366, in _close\n",
      "    _close(self._handle)\n",
      "  File \"/usr/lib/python3.9/multiprocessing/connection.py\", line 366, in _close\n",
      "    _close(self._handle)\n",
      "  File \"/usr/lib/python3.9/multiprocessing/connection.py\", line 366, in _close\n",
      "    _close(self._handle)\n",
      "  File \"/usr/lib/python3.9/multiprocessing/connection.py\", line 366, in _close\n",
      "    _close(self._handle)\n",
      "  File \"/usr/lib/python3.9/multiprocessing/connection.py\", line 182, in close\n",
      "    self._close()\n",
      "  File \"/usr/lib/python3.9/multiprocessing/connection.py\", line 366, in _close\n",
      "    _close(self._handle)\n",
      "  File \"/usr/lib/python3.9/multiprocessing/connection.py\", line 366, in _close\n",
      "    _close(self._handle)\n",
      "  File \"/usr/lib/python3.9/multiprocessing/connection.py\", line 182, in close\n",
      "    self._close()\n",
      "OSError: [Errno 9] Bad file descriptor\n",
      "  File \"/usr/lib/python3.9/multiprocessing/connection.py\", line 182, in close\n",
      "    self._close()\n",
      "  File \"/usr/lib/python3.9/multiprocessing/connection.py\", line 366, in _close\n",
      "    _close(self._handle)\n",
      "  File \"/usr/lib/python3.9/multiprocessing/connection.py\", line 182, in close\n",
      "    self._close()\n",
      "  File \"/usr/lib/python3.9/multiprocessing/connection.py\", line 366, in _close\n",
      "    _close(self._handle)\n",
      "  File \"/usr/lib/python3.9/multiprocessing/connection.py\", line 366, in _close\n",
      "    _close(self._handle)\n",
      "  File \"/usr/lib/python3.9/multiprocessing/connection.py\", line 182, in close\n",
      "    self._close()\n",
      "  File \"/usr/lib/python3.9/multiprocessing/connection.py\", line 366, in _close\n",
      "    _close(self._handle)\n",
      "  File \"/usr/lib/python3.9/multiprocessing/connection.py\", line 366, in _close\n",
      "    _close(self._handle)\n",
      "  File \"/usr/lib/python3.9/multiprocessing/connection.py\", line 366, in _close\n",
      "    _close(self._handle)\n",
      "  File \"/usr/lib/python3.9/multiprocessing/connection.py\", line 182, in close\n",
      "    self._close()\n",
      "  File \"/usr/lib/python3.9/multiprocessing/connection.py\", line 366, in _close\n",
      "    _close(self._handle)\n",
      "  File \"/usr/lib/python3.9/multiprocessing/connection.py\", line 182, in close\n",
      "    self._close()\n",
      "  File \"/usr/lib/python3.9/multiprocessing/connection.py\", line 366, in _close\n",
      "    _close(self._handle)\n",
      "  File \"/usr/lib/python3.9/multiprocessing/connection.py\", line 366, in _close\n",
      "    _close(self._handle)\n",
      "  File \"/usr/lib/python3.9/multiprocessing/connection.py\", line 366, in _close\n",
      "    _close(self._handle)\n",
      "  File \"/usr/lib/python3.9/multiprocessing/connection.py\", line 366, in _close\n",
      "    _close(self._handle)\n",
      "  File \"/usr/lib/python3.9/multiprocessing/connection.py\", line 366, in _close\n",
      "    _close(self._handle)\n",
      "  File \"/usr/lib/python3.9/multiprocessing/connection.py\", line 366, in _close\n",
      "    _close(self._handle)\n",
      "  File \"/usr/lib/python3.9/multiprocessing/connection.py\", line 366, in _close\n",
      "    _close(self._handle)\n",
      "  File \"/usr/lib/python3.9/multiprocessing/connection.py\", line 366, in _close\n",
      "    _close(self._handle)\n",
      "  File \"/usr/lib/python3.9/multiprocessing/connection.py\", line 366, in _close\n",
      "    _close(self._handle)\n",
      "  File \"/usr/lib/python3.9/multiprocessing/connection.py\", line 366, in _close\n",
      "    _close(self._handle)\n",
      "  File \"/usr/lib/python3.9/multiprocessing/connection.py\", line 366, in _close\n",
      "    _close(self._handle)\n",
      "  File \"/usr/lib/python3.9/multiprocessing/connection.py\", line 182, in close\n",
      "    self._close()\n",
      "  File \"/usr/lib/python3.9/multiprocessing/connection.py\", line 366, in _close\n",
      "    _close(self._handle)\n",
      "  File \"/usr/lib/python3.9/multiprocessing/connection.py\", line 366, in _close\n",
      "    _close(self._handle)\n",
      "OSError: [Errno 9] Bad file descriptor\n",
      "  File \"/usr/lib/python3.9/multiprocessing/connection.py\", line 366, in _close\n",
      "    _close(self._handle)\n",
      "  File \"/usr/lib/python3.9/multiprocessing/connection.py\", line 366, in _close\n",
      "    _close(self._handle)\n",
      "  File \"/usr/lib/python3.9/multiprocessing/connection.py\", line 366, in _close\n",
      "    _close(self._handle)\n",
      "  File \"/usr/lib/python3.9/multiprocessing/connection.py\", line 366, in _close\n",
      "    _close(self._handle)\n",
      "  File \"/usr/lib/python3.9/multiprocessing/connection.py\", line 366, in _close\n",
      "    _close(self._handle)\n",
      "  File \"/usr/lib/python3.9/multiprocessing/connection.py\", line 366, in _close\n",
      "    _close(self._handle)\n",
      "  File \"/usr/lib/python3.9/multiprocessing/connection.py\", line 366, in _close\n",
      "    _close(self._handle)\n",
      "  File \"/usr/lib/python3.9/multiprocessing/connection.py\", line 366, in _close\n",
      "    _close(self._handle)\n",
      "  File \"/usr/lib/python3.9/multiprocessing/connection.py\", line 366, in _close\n",
      "    _close(self._handle)\n",
      "  File \"/usr/lib/python3.9/multiprocessing/connection.py\", line 366, in _close\n",
      "    _close(self._handle)\n",
      "  File \"/usr/lib/python3.9/multiprocessing/connection.py\", line 366, in _close\n",
      "    _close(self._handle)\n",
      "  File \"/usr/lib/python3.9/multiprocessing/connection.py\", line 366, in _close\n",
      "    _close(self._handle)\n",
      "OSError: [Errno 9] Bad file descriptor\n",
      "  File \"/usr/lib/python3.9/multiprocessing/connection.py\", line 366, in _close\n",
      "    _close(self._handle)\n",
      "  File \"/usr/lib/python3.9/multiprocessing/connection.py\", line 366, in _close\n",
      "    _close(self._handle)\n",
      "  File \"/usr/lib/python3.9/multiprocessing/connection.py\", line 366, in _close\n",
      "    _close(self._handle)\n",
      "OSError: [Errno 9] Bad file descriptor\n",
      "OSError: [Errno 9] Bad file descriptor\n",
      "OSError: [Errno 9] Bad file descriptor\n",
      "  File \"/usr/lib/python3.9/multiprocessing/connection.py\", line 366, in _close\n",
      "    _close(self._handle)\n",
      "OSError: [Errno 9] Bad file descriptor\n",
      "OSError: [Errno 9] Bad file descriptor\n",
      "OSError: [Errno 9] Bad file descriptor\n",
      "  File \"/usr/lib/python3.9/multiprocessing/connection.py\", line 366, in _close\n",
      "    _close(self._handle)\n",
      "  File \"/usr/lib/python3.9/multiprocessing/connection.py\", line 366, in _close\n",
      "    _close(self._handle)\n",
      "OSError: [Errno 9] Bad file descriptor\n",
      "  File \"/usr/lib/python3.9/multiprocessing/connection.py\", line 366, in _close\n",
      "    _close(self._handle)\n",
      "  File \"/usr/lib/python3.9/multiprocessing/connection.py\", line 182, in close\n",
      "    self._close()\n",
      "  File \"/usr/lib/python3.9/multiprocessing/connection.py\", line 366, in _close\n",
      "    _close(self._handle)\n",
      "OSError: [Errno 9] Bad file descriptor\n",
      "OSError: [Errno 9] Bad file descriptor\n",
      "OSError: [Errno 9] Bad file descriptor\n",
      "  File \"/usr/lib/python3.9/multiprocessing/connection.py\", line 366, in _close\n",
      "    _close(self._handle)\n",
      "  File \"/usr/lib/python3.9/multiprocessing/connection.py\", line 366, in _close\n",
      "    _close(self._handle)\n",
      "  File \"/usr/lib/python3.9/multiprocessing/connection.py\", line 366, in _close\n",
      "    _close(self._handle)\n",
      "OSError: [Errno 9] Bad file descriptor\n",
      "  File \"/usr/lib/python3.9/multiprocessing/connection.py\", line 366, in _close\n",
      "    _close(self._handle)\n",
      "OSError: [Errno 9] Bad file descriptor\n",
      "OSError: [Errno 9] Bad file descriptor\n",
      "OSError: [Errno 9] Bad file descriptor\n",
      "  File \"/usr/lib/python3.9/multiprocessing/connection.py\", line 366, in _close\n",
      "    _close(self._handle)\n",
      "  File \"/usr/lib/python3.9/multiprocessing/connection.py\", line 366, in _close\n",
      "    _close(self._handle)\n",
      "  File \"/usr/lib/python3.9/multiprocessing/connection.py\", line 366, in _close\n",
      "    _close(self._handle)\n",
      "OSError: [Errno 9] Bad file descriptor\n",
      "  File \"/usr/lib/python3.9/multiprocessing/connection.py\", line 366, in _close\n",
      "    _close(self._handle)\n",
      "  File \"/usr/lib/python3.9/multiprocessing/connection.py\", line 366, in _close\n",
      "    _close(self._handle)\n",
      "OSError: [Errno 9] Bad file descriptor\n",
      "  File \"/usr/lib/python3.9/multiprocessing/connection.py\", line 366, in _close\n",
      "    _close(self._handle)\n",
      "  File \"/usr/lib/python3.9/multiprocessing/connection.py\", line 366, in _close\n",
      "    _close(self._handle)\n",
      "  File \"/usr/lib/python3.9/multiprocessing/connection.py\", line 366, in _close\n",
      "    _close(self._handle)\n",
      "OSError: [Errno 9] Bad file descriptor\n",
      "  File \"/usr/lib/python3.9/multiprocessing/connection.py\", line 366, in _close\n",
      "    _close(self._handle)\n",
      "OSError: [Errno 9] Bad file descriptor\n",
      "OSError: [Errno 9] Bad file descriptor\n",
      "  File \"/usr/lib/python3.9/multiprocessing/connection.py\", line 366, in _close\n",
      "    _close(self._handle)\n",
      "  File \"/usr/lib/python3.9/multiprocessing/connection.py\", line 182, in close\n",
      "    self._close()\n",
      "OSError: [Errno 9] Bad file descriptor\n",
      "OSError: [Errno 9] Bad file descriptor\n",
      "  File \"/usr/lib/python3.9/multiprocessing/connection.py\", line 366, in _close\n",
      "    _close(self._handle)\n",
      "OSError: [Errno 9] Bad file descriptor\n",
      "  File \"/usr/lib/python3.9/multiprocessing/connection.py\", line 366, in _close\n",
      "    _close(self._handle)\n",
      "OSError: [Errno 9] Bad file descriptor\n",
      "OSError: [Errno 9] Bad file descriptor\n",
      "  File \"/usr/lib/python3.9/multiprocessing/connection.py\", line 366, in _close\n",
      "    _close(self._handle)\n",
      "OSError: [Errno 9] Bad file descriptor\n",
      "OSError: [Errno 9] Bad file descriptor\n",
      "OSError: [Errno 9] Bad file descriptor\n",
      "OSError: [Errno 9] Bad file descriptor\n",
      "  File \"/usr/lib/python3.9/multiprocessing/connection.py\", line 366, in _close\n",
      "    _close(self._handle)\n",
      "OSError: [Errno 9] Bad file descriptor\n",
      "OSError: [Errno 9] Bad file descriptor\n",
      "OSError: [Errno 9] Bad file descriptor\n",
      "OSError: [Errno 9] Bad file descriptor\n",
      "OSError: [Errno 9] Bad file descriptor\n",
      "OSError: [Errno 9] Bad file descriptor\n",
      "OSError: [Errno 9] Bad file descriptor\n",
      "OSError: [Errno 9] Bad file descriptor\n",
      "  File \"/usr/lib/python3.9/multiprocessing/connection.py\", line 366, in _close\n",
      "    _close(self._handle)\n",
      "OSError: [Errno 9] Bad file descriptor\n",
      "OSError: [Errno 9] Bad file descriptor\n",
      "OSError: [Errno 9] Bad file descriptor\n",
      "OSError: [Errno 9] Bad file descriptor\n",
      "OSError: [Errno 9] Bad file descriptor\n",
      "OSError: [Errno 9] Bad file descriptor\n",
      "OSError: [Errno 9] Bad file descriptor\n",
      "OSError: [Errno 9] Bad file descriptor\n",
      "OSError: [Errno 9] Bad file descriptor\n",
      "OSError: [Errno 9] Bad file descriptor\n",
      "OSError: [Errno 9] Bad file descriptor\n",
      "OSError: [Errno 9] Bad file descriptor\n",
      "OSError: [Errno 9] Bad file descriptor\n",
      "OSError: [Errno 9] Bad file descriptor\n",
      "OSError: [Errno 9] Bad file descriptor\n",
      "OSError: [Errno 9] Bad file descriptor\n",
      "OSError: [Errno 9] Bad file descriptor\n",
      "OSError: [Errno 9] Bad file descriptor\n",
      "  File \"/usr/lib/python3.9/multiprocessing/connection.py\", line 366, in _close\n",
      "    _close(self._handle)\n",
      "OSError: [Errno 9] Bad file descriptor\n",
      "OSError: [Errno 9] Bad file descriptor\n",
      "OSError: [Errno 9] Bad file descriptor\n",
      "OSError: [Errno 9] Bad file descriptor\n",
      "OSError: [Errno 9] Bad file descriptor\n",
      "OSError: [Errno 9] Bad file descriptor\n",
      "OSError: [Errno 9] Bad file descriptor\n",
      "OSError: [Errno 9] Bad file descriptor\n",
      "OSError: [Errno 9] Bad file descriptor\n",
      "OSError: [Errno 9] Bad file descriptor\n",
      "OSError: [Errno 9] Bad file descriptor\n",
      "OSError: [Errno 9] Bad file descriptor\n",
      "OSError: [Errno 9] Bad file descriptor\n",
      "OSError: [Errno 9] Bad file descriptor\n",
      "OSError: [Errno 9] Bad file descriptor\n",
      "OSError: [Errno 9] Bad file descriptor\n",
      "OSError: [Errno 9] Bad file descriptor\n",
      "OSError: [Errno 9] Bad file descriptor\n",
      "  File \"/usr/lib/python3.9/multiprocessing/connection.py\", line 366, in _close\n",
      "    _close(self._handle)\n",
      "OSError: [Errno 9] Bad file descriptor\n",
      "OSError: [Errno 9] Bad file descriptor\n",
      "OSError: [Errno 9] Bad file descriptor\n",
      "OSError: [Errno 9] Bad file descriptor\n",
      "OSError: [Errno 9] Bad file descriptor\n",
      "Validation:   3%|▎         | 2/61 [00:05<02:12,  2.25s/batch]Exception ignored in: <function _MultiProcessingDataLoaderIter.__del__ at 0x7f6683c88040>\n",
      "Traceback (most recent call last):\n",
      "  File \"/usr/local/lib/python3.9/dist-packages/torch/utils/data/dataloader.py\", line 1604, in __del__\n",
      "    self._shutdown_workers()\n",
      "  File \"/usr/local/lib/python3.9/dist-packages/torch/utils/data/dataloader.py\", line 1587, in _shutdown_workers\n",
      "    if w.is_alive():\n",
      "  File \"/usr/lib/python3.9/multiprocessing/process.py\", line 160, in is_alive\n",
      "Exception ignored in:     <function _MultiProcessingDataLoaderIter.__del__ at 0x7f6683c88040>\n",
      "Traceback (most recent call last):\n",
      "  File \"/usr/local/lib/python3.9/dist-packages/torch/utils/data/dataloader.py\", line 1604, in __del__\n",
      "assert self._parent_pid == os.getpid(), 'can only test a child process'    self._shutdown_workers()\n",
      "  File \"/usr/local/lib/python3.9/dist-packages/torch/utils/data/dataloader.py\", line 1587, in _shutdown_workers\n",
      "    if w.is_alive():\n",
      "\n",
      "  File \"/usr/lib/python3.9/multiprocessing/process.py\", line 160, in is_alive\n",
      "AssertionError    : assert self._parent_pid == os.getpid(), 'can only test a child process'can only test a child process\n",
      "AssertionError: \n",
      "can only test a child process\n",
      "Exception ignored in: <function _MultiProcessingDataLoaderIter.__del__ at 0x7f6683c88040>Exception ignored in: \n",
      "Traceback (most recent call last):\n",
      "  File \"/usr/local/lib/python3.9/dist-packages/torch/utils/data/dataloader.py\", line 1604, in __del__\n",
      "Validation:   5%|▍         | 3/61 [00:05<01:16,  1.32s/batch]    <function _MultiProcessingDataLoaderIter.__del__ at 0x7f6683c88040>self._shutdown_workers()\n",
      "\n",
      "Traceback (most recent call last):\n",
      "  File \"/usr/local/lib/python3.9/dist-packages/torch/utils/data/dataloader.py\", line 1587, in _shutdown_workers\n",
      "  File \"/usr/local/lib/python3.9/dist-packages/torch/utils/data/dataloader.py\", line 1604, in __del__\n",
      "    if w.is_alive():\n",
      "      File \"/usr/lib/python3.9/multiprocessing/process.py\", line 160, in is_alive\n",
      "self._shutdown_workers()    \n",
      "assert self._parent_pid == os.getpid(), 'can only test a child process'\n",
      "AssertionError: can only test a child process\n",
      "  File \"/usr/local/lib/python3.9/dist-packages/torch/utils/data/dataloader.py\", line 1587, in _shutdown_workers\n",
      "    if w.is_alive():\n",
      "  File \"/usr/lib/python3.9/multiprocessing/process.py\", line 160, in is_alive\n",
      "    assert self._parent_pid == os.getpid(), 'can only test a child process'\n",
      "AssertionError: can only test a child process\n",
      "Exception ignored in: <function _MultiProcessingDataLoaderIter.__del__ at 0x7f6683c88040>\n",
      "Traceback (most recent call last):\n",
      "  File \"/usr/local/lib/python3.9/dist-packages/torch/utils/data/dataloader.py\", line 1604, in __del__\n",
      "    self._shutdown_workers()\n",
      "  File \"/usr/local/lib/python3.9/dist-packages/torch/utils/data/dataloader.py\", line 1587, in _shutdown_workers\n",
      "    if w.is_alive():\n",
      "  File \"/usr/lib/python3.9/multiprocessing/process.py\", line 160, in is_alive\n",
      "    assert self._parent_pid == os.getpid(), 'can only test a child process'\n",
      "Exception ignored in: AssertionError<function _MultiProcessingDataLoaderIter.__del__ at 0x7f6683c88040>: \n",
      "Traceback (most recent call last):\n",
      "  File \"/usr/local/lib/python3.9/dist-packages/torch/utils/data/dataloader.py\", line 1604, in __del__\n",
      "    self._shutdown_workers()can only test a child process\n",
      "\n",
      "  File \"/usr/local/lib/python3.9/dist-packages/torch/utils/data/dataloader.py\", line 1587, in _shutdown_workers\n",
      "    if w.is_alive():\n",
      "  File \"/usr/lib/python3.9/multiprocessing/process.py\", line 160, in is_alive\n",
      "    assert self._parent_pid == os.getpid(), 'can only test a child process'\n",
      "AssertionError: can only test a child processException ignored in: \n",
      "<function _MultiProcessingDataLoaderIter.__del__ at 0x7f6683c88040>\n",
      "Traceback (most recent call last):\n",
      "  File \"/usr/local/lib/python3.9/dist-packages/torch/utils/data/dataloader.py\", line 1604, in __del__\n",
      "    self._shutdown_workers()\n",
      "  File \"/usr/local/lib/python3.9/dist-packages/torch/utils/data/dataloader.py\", line 1587, in _shutdown_workers\n",
      "    if w.is_alive():\n",
      "  File \"/usr/lib/python3.9/multiprocessing/process.py\", line 160, in is_alive\n",
      "    assert self._parent_pid == os.getpid(), 'can only test a child process'\n",
      "AssertionError: can only test a child process\n",
      "Exception ignored in: <function _MultiProcessingDataLoaderIter.__del__ at 0x7f6683c88040>\n",
      "Traceback (most recent call last):\n",
      "  File \"/usr/local/lib/python3.9/dist-packages/torch/utils/data/dataloader.py\", line 1604, in __del__\n",
      "Validation:   7%|▋         | 4/61 [00:05<00:50,  1.13batch/s]    self._shutdown_workers()\n",
      "  File \"/usr/local/lib/python3.9/dist-packages/torch/utils/data/dataloader.py\", line 1587, in _shutdown_workers\n",
      "    if w.is_alive():Exception ignored in: \n",
      "<function _MultiProcessingDataLoaderIter.__del__ at 0x7f6683c88040>  File \"/usr/lib/python3.9/multiprocessing/process.py\", line 160, in is_alive\n",
      "\n",
      "    Traceback (most recent call last):\n",
      "  File \"/usr/local/lib/python3.9/dist-packages/torch/utils/data/dataloader.py\", line 1604, in __del__\n",
      "assert self._parent_pid == os.getpid(), 'can only test a child process'\n",
      "    AssertionErrorself._shutdown_workers()assert self._parent_pid == os.getpid(), 'can only test a child process': \n",
      "can only test a child process  File \"/usr/local/lib/python3.9/dist-packages/torch/utils/data/dataloader.py\", line 1587, in _shutdown_workers\n",
      "\n",
      "    if w.is_alive():\n",
      "  File \"/usr/lib/python3.9/multiprocessing/process.py\", line 160, in is_alive\n",
      "    \n",
      "AssertionError: can only test a child process\n",
      "Exception ignored in: <function _MultiProcessingDataLoaderIter.__del__ at 0x7f6683c88040>\n",
      "Traceback (most recent call last):\n",
      "  File \"/usr/local/lib/python3.9/dist-packages/torch/utils/data/dataloader.py\", line 1604, in __del__\n",
      "    self._shutdown_workers()\n",
      "  File \"/usr/local/lib/python3.9/dist-packages/torch/utils/data/dataloader.py\", line 1587, in _shutdown_workers\n",
      "    if w.is_alive():\n",
      "  File \"/usr/lib/python3.9/multiprocessing/process.py\", line 160, in is_alive\n",
      "    assert self._parent_pid == os.getpid(), 'can only test a child process'\n",
      "Exception ignored in: <function _MultiProcessingDataLoaderIter.__del__ at 0x7f6683c88040>\n",
      "Traceback (most recent call last):\n",
      "  File \"/usr/local/lib/python3.9/dist-packages/torch/utils/data/dataloader.py\", line 1604, in __del__\n",
      "    self._shutdown_workers()\n",
      "AssertionError  File \"/usr/local/lib/python3.9/dist-packages/torch/utils/data/dataloader.py\", line 1587, in _shutdown_workers\n",
      "    if w.is_alive():: \n",
      "can only test a child process  File \"/usr/lib/python3.9/multiprocessing/process.py\", line 160, in is_alive\n",
      "\n",
      "    assert self._parent_pid == os.getpid(), 'can only test a child process'\n",
      "AssertionError: can only test a child process\n",
      "Exception ignored in: <function _MultiProcessingDataLoaderIter.__del__ at 0x7f6683c88040>\n",
      "Traceback (most recent call last):\n",
      "  File \"/usr/local/lib/python3.9/dist-packages/torch/utils/data/dataloader.py\", line 1604, in __del__\n",
      "    self._shutdown_workers()\n",
      "  File \"/usr/local/lib/python3.9/dist-packages/torch/utils/data/dataloader.py\", line 1587, in _shutdown_workers\n",
      "    if w.is_alive():\n",
      "  File \"/usr/lib/python3.9/multiprocessing/process.py\", line 160, in is_alive\n",
      "    assert self._parent_pid == os.getpid(), 'can only test a child process'\n",
      "AssertionErrorTraceback (most recent call last):\n",
      "Traceback (most recent call last):\n",
      ": Traceback (most recent call last):\n",
      "Traceback (most recent call last):\n",
      "Traceback (most recent call last):\n",
      "  File \"/usr/lib/python3.9/multiprocessing/queues.py\", line 241, in _feed\n",
      "    close()\n",
      "can only test a child processTraceback (most recent call last):\n",
      "\n",
      "Traceback (most recent call last):\n",
      "  File \"/usr/lib/python3.9/multiprocessing/connection.py\", line 182, in close\n",
      "    self._close()\n",
      "Traceback (most recent call last):\n",
      "Traceback (most recent call last):\n",
      "Traceback (most recent call last):\n",
      "Traceback (most recent call last):\n",
      "Traceback (most recent call last):\n",
      "Traceback (most recent call last):\n",
      "Traceback (most recent call last):\n",
      "Traceback (most recent call last):\n",
      "Traceback (most recent call last):\n",
      "  File \"/usr/lib/python3.9/multiprocessing/queues.py\", line 241, in _feed\n",
      "    close()\n",
      "Traceback (most recent call last):\n",
      "Traceback (most recent call last):\n",
      "  File \"/usr/lib/python3.9/multiprocessing/queues.py\", line 241, in _feed\n",
      "    close()\n",
      "  File \"/usr/lib/python3.9/multiprocessing/queues.py\", line 241, in _feed\n",
      "    close()\n",
      "Traceback (most recent call last):\n",
      "  File \"/usr/lib/python3.9/multiprocessing/queues.py\", line 241, in _feed\n",
      "    close()\n",
      "Traceback (most recent call last):\n",
      "Traceback (most recent call last):\n",
      "Traceback (most recent call last):\n",
      "Traceback (most recent call last):\n",
      "Traceback (most recent call last):\n",
      "Traceback (most recent call last):\n",
      "  File \"/usr/lib/python3.9/multiprocessing/queues.py\", line 241, in _feed\n",
      "    close()\n",
      "  File \"/usr/lib/python3.9/multiprocessing/queues.py\", line 241, in _feed\n",
      "    close()\n",
      "Traceback (most recent call last):\n",
      "Traceback (most recent call last):\n",
      "  File \"/usr/lib/python3.9/multiprocessing/queues.py\", line 241, in _feed\n",
      "    close()\n",
      "  File \"/usr/lib/python3.9/multiprocessing/connection.py\", line 366, in _close\n",
      "    _close(self._handle)\n",
      "Traceback (most recent call last):\n",
      "Traceback (most recent call last):\n",
      "  File \"/usr/lib/python3.9/multiprocessing/queues.py\", line 241, in _feed\n",
      "    close()\n",
      "Traceback (most recent call last):\n",
      "Traceback (most recent call last):\n",
      "Traceback (most recent call last):\n",
      "  File \"/usr/lib/python3.9/multiprocessing/queues.py\", line 241, in _feed\n",
      "    close()\n",
      "  File \"/usr/lib/python3.9/multiprocessing/connection.py\", line 182, in close\n",
      "    self._close()\n",
      "Traceback (most recent call last):\n",
      "  File \"/usr/lib/python3.9/multiprocessing/connection.py\", line 182, in close\n",
      "    self._close()\n",
      "  File \"/usr/lib/python3.9/multiprocessing/connection.py\", line 182, in close\n",
      "    self._close()\n",
      "Traceback (most recent call last):\n",
      "  File \"/usr/lib/python3.9/multiprocessing/connection.py\", line 182, in close\n",
      "    self._close()\n",
      "  File \"/usr/lib/python3.9/multiprocessing/queues.py\", line 241, in _feed\n",
      "    close()\n",
      "  File \"/usr/lib/python3.9/multiprocessing/connection.py\", line 182, in close\n",
      "    self._close()\n",
      "Validation:   8%|▊         | 5/61 [00:06<00:36,  1.55batch/s]  File \"/usr/lib/python3.9/multiprocessing/queues.py\", line 241, in _feed\n",
      "    close()\n",
      "OSError: [Errno 9] Bad file descriptor\n",
      "Traceback (most recent call last):\n",
      "  File \"/usr/lib/python3.9/multiprocessing/queues.py\", line 241, in _feed\n",
      "    close()\n",
      "  File \"/usr/lib/python3.9/multiprocessing/queues.py\", line 241, in _feed\n",
      "    close()\n",
      "  File \"/usr/lib/python3.9/multiprocessing/queues.py\", line 241, in _feed\n",
      "    close()\n",
      "  File \"/usr/lib/python3.9/multiprocessing/connection.py\", line 366, in _close\n",
      "    _close(self._handle)\n",
      "  File \"/usr/lib/python3.9/multiprocessing/queues.py\", line 241, in _feed\n",
      "    close()\n",
      "  File \"/usr/lib/python3.9/multiprocessing/connection.py\", line 366, in _close\n",
      "    _close(self._handle)\n",
      "  File \"/usr/lib/python3.9/multiprocessing/queues.py\", line 241, in _feed\n",
      "    close()\n",
      "Traceback (most recent call last):\n",
      "Traceback (most recent call last):\n",
      "  File \"/usr/lib/python3.9/multiprocessing/queues.py\", line 241, in _feed\n",
      "    close()\n",
      "  File \"/usr/lib/python3.9/multiprocessing/queues.py\", line 241, in _feed\n",
      "    close()\n",
      "  File \"/usr/lib/python3.9/multiprocessing/connection.py\", line 182, in close\n",
      "    self._close()\n",
      "  File \"/usr/lib/python3.9/multiprocessing/queues.py\", line 241, in _feed\n",
      "    close()\n",
      "Traceback (most recent call last):\n",
      "  File \"/usr/lib/python3.9/multiprocessing/connection.py\", line 182, in close\n",
      "    self._close()\n",
      "  File \"/usr/lib/python3.9/multiprocessing/connection.py\", line 366, in _close\n",
      "    _close(self._handle)\n",
      "  File \"/usr/lib/python3.9/multiprocessing/queues.py\", line 241, in _feed\n",
      "    close()\n",
      "  File \"/usr/lib/python3.9/multiprocessing/queues.py\", line 241, in _feed\n",
      "    close()\n",
      "  File \"/usr/lib/python3.9/multiprocessing/queues.py\", line 241, in _feed\n",
      "    close()\n",
      "OSError: [Errno 9] Bad file descriptor\n",
      "  File \"/usr/lib/python3.9/multiprocessing/connection.py\", line 182, in close\n",
      "    self._close()\n",
      "  File \"/usr/lib/python3.9/multiprocessing/queues.py\", line 241, in _feed\n",
      "    close()\n",
      "Traceback (most recent call last):\n",
      "  File \"/usr/lib/python3.9/multiprocessing/queues.py\", line 241, in _feed\n",
      "    close()\n",
      "  File \"/usr/lib/python3.9/multiprocessing/queues.py\", line 241, in _feed\n",
      "    close()\n",
      "OSError: [Errno 9] Bad file descriptor\n",
      "Traceback (most recent call last):\n",
      "  File \"/usr/lib/python3.9/multiprocessing/connection.py\", line 182, in close\n",
      "    self._close()\n",
      "  File \"/usr/lib/python3.9/multiprocessing/queues.py\", line 241, in _feed\n",
      "    close()\n",
      "Traceback (most recent call last):\n",
      "Traceback (most recent call last):\n",
      "  File \"/usr/lib/python3.9/multiprocessing/queues.py\", line 241, in _feed\n",
      "    close()\n",
      "  File \"/usr/lib/python3.9/multiprocessing/connection.py\", line 182, in close\n",
      "    self._close()\n",
      "Traceback (most recent call last):\n",
      "  File \"/usr/lib/python3.9/multiprocessing/queues.py\", line 241, in _feed\n",
      "    close()\n",
      "Traceback (most recent call last):\n",
      "  File \"/usr/lib/python3.9/multiprocessing/connection.py\", line 366, in _close\n",
      "    _close(self._handle)\n",
      "  File \"/usr/lib/python3.9/multiprocessing/queues.py\", line 241, in _feed\n",
      "    close()\n",
      "  File \"/usr/lib/python3.9/multiprocessing/connection.py\", line 182, in close\n",
      "    self._close()\n",
      "  File \"/usr/lib/python3.9/multiprocessing/connection.py\", line 182, in close\n",
      "    self._close()\n",
      "Traceback (most recent call last):\n",
      "  File \"/usr/lib/python3.9/multiprocessing/connection.py\", line 182, in close\n",
      "    self._close()\n",
      "  File \"/usr/lib/python3.9/multiprocessing/connection.py\", line 366, in _close\n",
      "    _close(self._handle)\n",
      "  File \"/usr/lib/python3.9/multiprocessing/queues.py\", line 241, in _feed\n",
      "    close()\n",
      "  File \"/usr/lib/python3.9/multiprocessing/queues.py\", line 241, in _feed\n",
      "    close()\n",
      "Traceback (most recent call last):\n",
      "Traceback (most recent call last):\n",
      "  File \"/usr/lib/python3.9/multiprocessing/connection.py\", line 182, in close\n",
      "    self._close()\n",
      "  File \"/usr/lib/python3.9/multiprocessing/connection.py\", line 182, in close\n",
      "    self._close()\n",
      "  File \"/usr/lib/python3.9/multiprocessing/queues.py\", line 241, in _feed\n",
      "    close()\n",
      "  File \"/usr/lib/python3.9/multiprocessing/connection.py\", line 366, in _close\n",
      "    _close(self._handle)\n",
      "Traceback (most recent call last):\n",
      "  File \"/usr/lib/python3.9/multiprocessing/connection.py\", line 182, in close\n",
      "    self._close()\n",
      "  File \"/usr/lib/python3.9/multiprocessing/connection.py\", line 366, in _close\n",
      "    _close(self._handle)\n",
      "  File \"/usr/lib/python3.9/multiprocessing/connection.py\", line 366, in _close\n",
      "    _close(self._handle)\n",
      "  File \"/usr/lib/python3.9/multiprocessing/connection.py\", line 182, in close\n",
      "    self._close()\n",
      "  File \"/usr/lib/python3.9/multiprocessing/connection.py\", line 366, in _close\n",
      "    _close(self._handle)\n",
      "Traceback (most recent call last):\n",
      "Traceback (most recent call last):\n",
      "  File \"/usr/lib/python3.9/multiprocessing/queues.py\", line 241, in _feed\n",
      "    close()\n",
      "Traceback (most recent call last):\n",
      "  File \"/usr/lib/python3.9/multiprocessing/queues.py\", line 241, in _feed\n",
      "    close()\n",
      "Traceback (most recent call last):\n",
      "Traceback (most recent call last):\n",
      "Traceback (most recent call last):\n",
      "OSError: [Errno 9] Bad file descriptor\n",
      "OSError: [Errno 9] Bad file descriptor\n",
      "Traceback (most recent call last):\n",
      "  File \"/usr/lib/python3.9/multiprocessing/queues.py\", line 241, in _feed\n",
      "    close()\n",
      "Traceback (most recent call last):\n",
      "  File \"/usr/lib/python3.9/multiprocessing/queues.py\", line 241, in _feed\n",
      "    close()\n",
      "  File \"/usr/lib/python3.9/multiprocessing/connection.py\", line 182, in close\n",
      "    self._close()\n",
      "  File \"/usr/lib/python3.9/multiprocessing/connection.py\", line 182, in close\n",
      "    self._close()\n",
      "  File \"/usr/lib/python3.9/multiprocessing/queues.py\", line 241, in _feed\n",
      "    close()\n",
      "Traceback (most recent call last):\n",
      "  File \"/usr/lib/python3.9/multiprocessing/connection.py\", line 182, in close\n",
      "    self._close()\n",
      "  File \"/usr/lib/python3.9/multiprocessing/queues.py\", line 241, in _feed\n",
      "    close()\n",
      "  File \"/usr/lib/python3.9/multiprocessing/queues.py\", line 241, in _feed\n",
      "    close()\n",
      "  File \"/usr/lib/python3.9/multiprocessing/connection.py\", line 366, in _close\n",
      "    _close(self._handle)\n",
      "  File \"/usr/lib/python3.9/multiprocessing/connection.py\", line 182, in close\n",
      "    self._close()\n",
      "  File \"/usr/lib/python3.9/multiprocessing/connection.py\", line 366, in _close\n",
      "    _close(self._handle)\n",
      "  File \"/usr/lib/python3.9/multiprocessing/queues.py\", line 241, in _feed\n",
      "    close()\n",
      "  File \"/usr/lib/python3.9/multiprocessing/connection.py\", line 182, in close\n",
      "    self._close()\n",
      "  File \"/usr/lib/python3.9/multiprocessing/queues.py\", line 241, in _feed\n",
      "    close()\n",
      "  File \"/usr/lib/python3.9/multiprocessing/connection.py\", line 182, in close\n",
      "    self._close()\n",
      "Traceback (most recent call last):\n",
      "  File \"/usr/lib/python3.9/multiprocessing/connection.py\", line 182, in close\n",
      "    self._close()\n",
      "  File \"/usr/lib/python3.9/multiprocessing/connection.py\", line 366, in _close\n",
      "    _close(self._handle)\n",
      "  File \"/usr/lib/python3.9/multiprocessing/connection.py\", line 366, in _close\n",
      "    _close(self._handle)\n",
      "Traceback (most recent call last):\n",
      "Traceback (most recent call last):\n",
      "  File \"/usr/lib/python3.9/multiprocessing/queues.py\", line 241, in _feed\n",
      "    close()\n",
      "OSError: [Errno 9] Bad file descriptor\n",
      "  File \"/usr/lib/python3.9/multiprocessing/connection.py\", line 182, in close\n",
      "    self._close()\n",
      "  File \"/usr/lib/python3.9/multiprocessing/connection.py\", line 182, in close\n",
      "    self._close()\n",
      "  File \"/usr/lib/python3.9/multiprocessing/queues.py\", line 241, in _feed\n",
      "    close()\n",
      "  File \"/usr/lib/python3.9/multiprocessing/connection.py\", line 182, in close\n",
      "    self._close()\n",
      "OSError: [Errno 9] Bad file descriptor\n",
      "  File \"/usr/lib/python3.9/multiprocessing/connection.py\", line 366, in _close\n",
      "    _close(self._handle)\n",
      "  File \"/usr/lib/python3.9/multiprocessing/connection.py\", line 182, in close\n",
      "    self._close()\n",
      "  File \"/usr/lib/python3.9/multiprocessing/connection.py\", line 366, in _close\n",
      "    _close(self._handle)\n",
      "Traceback (most recent call last):\n",
      "  File \"/usr/lib/python3.9/multiprocessing/connection.py\", line 182, in close\n",
      "    self._close()\n",
      "  File \"/usr/lib/python3.9/multiprocessing/connection.py\", line 366, in _close\n",
      "    _close(self._handle)\n",
      "Traceback (most recent call last):\n",
      "  File \"/usr/lib/python3.9/multiprocessing/queues.py\", line 241, in _feed\n",
      "    close()\n",
      "OSError: [Errno 9] Bad file descriptor\n",
      "Traceback (most recent call last):\n",
      "  File \"/usr/lib/python3.9/multiprocessing/connection.py\", line 182, in close\n",
      "    self._close()\n",
      "Traceback (most recent call last):\n",
      "  File \"/usr/lib/python3.9/multiprocessing/queues.py\", line 241, in _feed\n",
      "    close()\n",
      "  File \"/usr/lib/python3.9/multiprocessing/connection.py\", line 366, in _close\n",
      "    _close(self._handle)\n",
      "  File \"/usr/lib/python3.9/multiprocessing/connection.py\", line 366, in _close\n",
      "    _close(self._handle)\n",
      "  File \"/usr/lib/python3.9/multiprocessing/connection.py\", line 182, in close\n",
      "    self._close()\n",
      "OSError: [Errno 9] Bad file descriptor\n",
      "OSError: [Errno 9] Bad file descriptor\n",
      "OSError: [Errno 9] Bad file descriptor\n",
      "  File \"/usr/lib/python3.9/multiprocessing/connection.py\", line 366, in _close\n",
      "    _close(self._handle)\n",
      "  File \"/usr/lib/python3.9/multiprocessing/connection.py\", line 366, in _close\n",
      "    _close(self._handle)\n",
      "  File \"/usr/lib/python3.9/multiprocessing/connection.py\", line 182, in close\n",
      "    self._close()\n",
      "  File \"/usr/lib/python3.9/multiprocessing/queues.py\", line 241, in _feed\n",
      "    close()\n",
      "Traceback (most recent call last):\n",
      "OSError: [Errno 9] Bad file descriptor\n",
      "  File \"/usr/lib/python3.9/multiprocessing/connection.py\", line 182, in close\n",
      "    self._close()\n",
      "  File \"/usr/lib/python3.9/multiprocessing/connection.py\", line 366, in _close\n",
      "    _close(self._handle)\n",
      "  File \"/usr/lib/python3.9/multiprocessing/connection.py\", line 182, in close\n",
      "    self._close()\n",
      "  File \"/usr/lib/python3.9/multiprocessing/connection.py\", line 182, in close\n",
      "    self._close()\n",
      "  File \"/usr/lib/python3.9/multiprocessing/queues.py\", line 241, in _feed\n",
      "    close()\n",
      "  File \"/usr/lib/python3.9/multiprocessing/connection.py\", line 182, in close\n",
      "    self._close()\n",
      "  File \"/usr/lib/python3.9/multiprocessing/queues.py\", line 241, in _feed\n",
      "    close()\n",
      "  File \"/usr/lib/python3.9/multiprocessing/connection.py\", line 366, in _close\n",
      "    _close(self._handle)\n",
      "OSError: [Errno 9] Bad file descriptor\n",
      "  File \"/usr/lib/python3.9/multiprocessing/queues.py\", line 241, in _feed\n",
      "    close()\n",
      "  File \"/usr/lib/python3.9/multiprocessing/queues.py\", line 241, in _feed\n",
      "    close()\n",
      "  File \"/usr/lib/python3.9/multiprocessing/connection.py\", line 182, in close\n",
      "    self._close()\n",
      "OSError: [Errno 9] Bad file descriptor\n",
      "OSError: [Errno 9] Bad file descriptor\n",
      "  File \"/usr/lib/python3.9/multiprocessing/connection.py\", line 366, in _close\n",
      "    _close(self._handle)\n",
      "  File \"/usr/lib/python3.9/multiprocessing/connection.py\", line 182, in close\n",
      "    self._close()\n",
      "OSError: [Errno 9] Bad file descriptor\n",
      "OSError: [Errno 9] Bad file descriptor\n",
      "OSError: [Errno 9] Bad file descriptor\n",
      "OSError: [Errno 9] Bad file descriptor\n",
      "  File \"/usr/lib/python3.9/multiprocessing/connection.py\", line 366, in _close\n",
      "    _close(self._handle)\n",
      "  File \"/usr/lib/python3.9/multiprocessing/queues.py\", line 241, in _feed\n",
      "    close()\n",
      "  File \"/usr/lib/python3.9/multiprocessing/queues.py\", line 241, in _feed\n",
      "    close()\n",
      "OSError: [Errno 9] Bad file descriptor\n",
      "Traceback (most recent call last):\n",
      "  File \"/usr/lib/python3.9/multiprocessing/connection.py\", line 366, in _close\n",
      "    _close(self._handle)\n",
      "OSError: [Errno 9] Bad file descriptor\n",
      "  File \"/usr/lib/python3.9/multiprocessing/queues.py\", line 241, in _feed\n",
      "    close()\n",
      "  File \"/usr/lib/python3.9/multiprocessing/queues.py\", line 241, in _feed\n",
      "    close()\n",
      "Traceback (most recent call last):\n",
      "  File \"/usr/lib/python3.9/multiprocessing/connection.py\", line 366, in _close\n",
      "    _close(self._handle)\n",
      "  File \"/usr/lib/python3.9/multiprocessing/queues.py\", line 241, in _feed\n",
      "    close()\n",
      "Traceback (most recent call last):\n",
      "  File \"/usr/lib/python3.9/multiprocessing/connection.py\", line 182, in close\n",
      "    self._close()\n",
      "  File \"/usr/lib/python3.9/multiprocessing/queues.py\", line 241, in _feed\n",
      "    close()\n",
      "Traceback (most recent call last):\n",
      "  File \"/usr/lib/python3.9/multiprocessing/queues.py\", line 241, in _feed\n",
      "    close()\n",
      "  File \"/usr/lib/python3.9/multiprocessing/connection.py\", line 182, in close\n",
      "    self._close()\n",
      "Traceback (most recent call last):\n",
      "  File \"/usr/lib/python3.9/multiprocessing/connection.py\", line 182, in close\n",
      "    self._close()\n",
      "  File \"/usr/lib/python3.9/multiprocessing/connection.py\", line 182, in close\n",
      "    self._close()\n",
      "OSError: [Errno 9] Bad file descriptor\n",
      "  File \"/usr/lib/python3.9/multiprocessing/connection.py\", line 366, in _close\n",
      "    _close(self._handle)\n",
      "OSError: [Errno 9] Bad file descriptor\n",
      "OSError: [Errno 9] Bad file descriptor\n",
      "  File \"/usr/lib/python3.9/multiprocessing/connection.py\", line 366, in _close\n",
      "    _close(self._handle)\n",
      "  File \"/usr/lib/python3.9/multiprocessing/connection.py\", line 182, in close\n",
      "    self._close()\n",
      "OSError: [Errno 9] Bad file descriptor\n",
      "  File \"/usr/lib/python3.9/multiprocessing/connection.py\", line 366, in _close\n",
      "    _close(self._handle)\n",
      "Traceback (most recent call last):\n",
      "Traceback (most recent call last):\n",
      "Traceback (most recent call last):\n",
      "  File \"/usr/lib/python3.9/multiprocessing/connection.py\", line 366, in _close\n",
      "    _close(self._handle)\n",
      "  File \"/usr/lib/python3.9/multiprocessing/connection.py\", line 366, in _close\n",
      "    _close(self._handle)\n",
      "Traceback (most recent call last):\n",
      "  File \"/usr/lib/python3.9/multiprocessing/connection.py\", line 366, in _close\n",
      "    _close(self._handle)\n",
      "OSError: [Errno 9] Bad file descriptor\n",
      "  File \"/usr/lib/python3.9/multiprocessing/connection.py\", line 366, in _close\n",
      "    _close(self._handle)\n",
      "  File \"/usr/lib/python3.9/multiprocessing/connection.py\", line 182, in close\n",
      "    self._close()\n",
      "  File \"/usr/lib/python3.9/multiprocessing/connection.py\", line 182, in close\n",
      "    self._close()\n",
      "  File \"/usr/lib/python3.9/multiprocessing/connection.py\", line 182, in close\n",
      "    self._close()\n",
      "  File \"/usr/lib/python3.9/multiprocessing/connection.py\", line 366, in _close\n",
      "    _close(self._handle)\n",
      "  File \"/usr/lib/python3.9/multiprocessing/connection.py\", line 366, in _close\n",
      "    _close(self._handle)\n",
      "Traceback (most recent call last):\n",
      "  File \"/usr/lib/python3.9/multiprocessing/connection.py\", line 182, in close\n",
      "    self._close()\n",
      "OSError: [Errno 9] Bad file descriptor\n",
      "  File \"/usr/lib/python3.9/multiprocessing/connection.py\", line 366, in _close\n",
      "    _close(self._handle)\n",
      "  File \"/usr/lib/python3.9/multiprocessing/connection.py\", line 182, in close\n",
      "    self._close()\n",
      "  File \"/usr/lib/python3.9/multiprocessing/connection.py\", line 366, in _close\n",
      "    _close(self._handle)\n",
      "  File \"/usr/lib/python3.9/multiprocessing/queues.py\", line 241, in _feed\n",
      "    close()\n",
      "  File \"/usr/lib/python3.9/multiprocessing/queues.py\", line 241, in _feed\n",
      "    close()\n",
      "  File \"/usr/lib/python3.9/multiprocessing/queues.py\", line 241, in _feed\n",
      "    close()\n",
      "  File \"/usr/lib/python3.9/multiprocessing/connection.py\", line 366, in _close\n",
      "    _close(self._handle)\n",
      "  File \"/usr/lib/python3.9/multiprocessing/queues.py\", line 241, in _feed\n",
      "    close()\n",
      "  File \"/usr/lib/python3.9/multiprocessing/connection.py\", line 366, in _close\n",
      "    _close(self._handle)\n",
      "  File \"/usr/lib/python3.9/multiprocessing/connection.py\", line 182, in close\n",
      "    self._close()\n",
      "  File \"/usr/lib/python3.9/multiprocessing/connection.py\", line 182, in close\n",
      "    self._close()\n",
      "  File \"/usr/lib/python3.9/multiprocessing/connection.py\", line 182, in close\n",
      "    self._close()\n",
      "  File \"/usr/lib/python3.9/multiprocessing/connection.py\", line 366, in _close\n",
      "    _close(self._handle)\n",
      "OSError: [Errno 9] Bad file descriptor\n",
      "OSError: [Errno 9] Bad file descriptor\n",
      "OSError: [Errno 9] Bad file descriptor\n",
      "  File \"/usr/lib/python3.9/multiprocessing/connection.py\", line 182, in close\n",
      "    self._close()\n",
      "  File \"/usr/lib/python3.9/multiprocessing/connection.py\", line 182, in close\n",
      "    self._close()\n",
      "OSError: [Errno 9] Bad file descriptor\n",
      "OSError: [Errno 9] Bad file descriptor\n",
      "  File \"/usr/lib/python3.9/multiprocessing/connection.py\", line 182, in close\n",
      "    self._close()\n",
      "OSError: [Errno 9] Bad file descriptor\n",
      "Traceback (most recent call last):\n",
      "Traceback (most recent call last):\n",
      "Traceback (most recent call last):\n",
      "OSError: [Errno 9] Bad file descriptor\n",
      "  File \"/usr/lib/python3.9/multiprocessing/connection.py\", line 366, in _close\n",
      "    _close(self._handle)\n",
      "OSError: [Errno 9] Bad file descriptor\n",
      "OSError: [Errno 9] Bad file descriptor\n",
      "OSError: [Errno 9] Bad file descriptor\n",
      "Traceback (most recent call last):\n",
      "OSError: [Errno 9] Bad file descriptor\n",
      "  File \"/usr/lib/python3.9/multiprocessing/queues.py\", line 241, in _feed\n",
      "    close()\n",
      "  File \"/usr/lib/python3.9/multiprocessing/queues.py\", line 241, in _feed\n",
      "    close()\n",
      "  File \"/usr/lib/python3.9/multiprocessing/queues.py\", line 241, in _feed\n",
      "    close()\n",
      "  File \"/usr/lib/python3.9/multiprocessing/connection.py\", line 366, in _close\n",
      "    _close(self._handle)\n",
      "  File \"/usr/lib/python3.9/multiprocessing/connection.py\", line 182, in close\n",
      "    self._close()\n",
      "  File \"/usr/lib/python3.9/multiprocessing/connection.py\", line 366, in _close\n",
      "    _close(self._handle)\n",
      "OSError: [Errno 9] Bad file descriptor\n",
      "OSError: [Errno 9] Bad file descriptor\n",
      "  File \"/usr/lib/python3.9/multiprocessing/connection.py\", line 182, in close\n",
      "    self._close()\n",
      "  File \"/usr/lib/python3.9/multiprocessing/queues.py\", line 241, in _feed\n",
      "    close()\n",
      "Traceback (most recent call last):\n",
      "  File \"/usr/lib/python3.9/multiprocessing/queues.py\", line 241, in _feed\n",
      "    close()\n",
      "  File \"/usr/lib/python3.9/multiprocessing/connection.py\", line 366, in _close\n",
      "    _close(self._handle)\n",
      "  File \"/usr/lib/python3.9/multiprocessing/connection.py\", line 366, in _close\n",
      "    _close(self._handle)\n",
      "  File \"/usr/lib/python3.9/multiprocessing/connection.py\", line 366, in _close\n",
      "    _close(self._handle)\n",
      "  File \"/usr/lib/python3.9/multiprocessing/queues.py\", line 241, in _feed\n",
      "    close()\n",
      "OSError: [Errno 9] Bad file descriptor\n",
      "  File \"/usr/lib/python3.9/multiprocessing/connection.py\", line 182, in close\n",
      "    self._close()\n",
      "  File \"/usr/lib/python3.9/multiprocessing/connection.py\", line 366, in _close\n",
      "    _close(self._handle)\n",
      "OSError: [Errno 9] Bad file descriptor\n",
      "  File \"/usr/lib/python3.9/multiprocessing/connection.py\", line 366, in _close\n",
      "    _close(self._handle)\n",
      "  File \"/usr/lib/python3.9/multiprocessing/queues.py\", line 241, in _feed\n",
      "    close()\n",
      "  File \"/usr/lib/python3.9/multiprocessing/queues.py\", line 241, in _feed\n",
      "    close()\n",
      "  File \"/usr/lib/python3.9/multiprocessing/connection.py\", line 366, in _close\n",
      "    _close(self._handle)\n",
      "  File \"/usr/lib/python3.9/multiprocessing/connection.py\", line 182, in close\n",
      "    self._close()\n",
      "  File \"/usr/lib/python3.9/multiprocessing/connection.py\", line 182, in close\n",
      "    self._close()\n",
      "  File \"/usr/lib/python3.9/multiprocessing/connection.py\", line 182, in close\n",
      "    self._close()\n",
      "  File \"/usr/lib/python3.9/multiprocessing/connection.py\", line 182, in close\n",
      "    self._close()\n",
      "  File \"/usr/lib/python3.9/multiprocessing/connection.py\", line 366, in _close\n",
      "    _close(self._handle)\n",
      "  File \"/usr/lib/python3.9/multiprocessing/queues.py\", line 241, in _feed\n",
      "    close()\n",
      "  File \"/usr/lib/python3.9/multiprocessing/connection.py\", line 366, in _close\n",
      "    _close(self._handle)\n",
      "  File \"/usr/lib/python3.9/multiprocessing/queues.py\", line 241, in _feed\n",
      "    close()\n",
      "  File \"/usr/lib/python3.9/multiprocessing/connection.py\", line 366, in _close\n",
      "    _close(self._handle)\n",
      "OSError: [Errno 9] Bad file descriptor\n",
      "  File \"/usr/lib/python3.9/multiprocessing/connection.py\", line 182, in close\n",
      "    self._close()\n",
      "  File \"/usr/lib/python3.9/multiprocessing/connection.py\", line 366, in _close\n",
      "    _close(self._handle)\n",
      "OSError: [Errno 9] Bad file descriptor\n",
      "  File \"/usr/lib/python3.9/multiprocessing/connection.py\", line 182, in close\n",
      "    self._close()\n",
      "OSError: [Errno 9] Bad file descriptor\n",
      "OSError: [Errno 9] Bad file descriptor\n",
      "  File \"/usr/lib/python3.9/multiprocessing/queues.py\", line 241, in _feed\n",
      "    close()\n",
      "OSError: [Errno 9] Bad file descriptor\n",
      "  File \"/usr/lib/python3.9/multiprocessing/connection.py\", line 182, in close\n",
      "    self._close()\n",
      "OSError: [Errno 9] Bad file descriptor\n",
      "  File \"/usr/lib/python3.9/multiprocessing/connection.py\", line 182, in close\n",
      "    self._close()\n",
      "  File \"/usr/lib/python3.9/multiprocessing/connection.py\", line 182, in close\n",
      "    self._close()\n",
      "OSError: [Errno 9] Bad file descriptor\n",
      "  File \"/usr/lib/python3.9/multiprocessing/queues.py\", line 241, in _feed\n",
      "    close()\n",
      "  File \"/usr/lib/python3.9/multiprocessing/queues.py\", line 241, in _feed\n",
      "    close()\n",
      "  File \"/usr/lib/python3.9/multiprocessing/queues.py\", line 241, in _feed\n",
      "    close()\n",
      "  File \"/usr/lib/python3.9/multiprocessing/connection.py\", line 366, in _close\n",
      "    _close(self._handle)\n",
      "  File \"/usr/lib/python3.9/multiprocessing/queues.py\", line 241, in _feed\n",
      "    close()\n",
      "  File \"/usr/lib/python3.9/multiprocessing/connection.py\", line 366, in _close\n",
      "    _close(self._handle)\n",
      "  File \"/usr/lib/python3.9/multiprocessing/connection.py\", line 182, in close\n",
      "    self._close()\n",
      "  File \"/usr/lib/python3.9/multiprocessing/connection.py\", line 182, in close\n",
      "    self._close()\n",
      "  File \"/usr/lib/python3.9/multiprocessing/connection.py\", line 182, in close\n",
      "    self._close()\n",
      "  File \"/usr/lib/python3.9/multiprocessing/connection.py\", line 366, in _close\n",
      "    _close(self._handle)\n",
      "  File \"/usr/lib/python3.9/multiprocessing/connection.py\", line 366, in _close\n",
      "    _close(self._handle)\n",
      "  File \"/usr/lib/python3.9/multiprocessing/queues.py\", line 241, in _feed\n",
      "    close()\n",
      "  File \"/usr/lib/python3.9/multiprocessing/queues.py\", line 241, in _feed\n",
      "    close()\n",
      "  File \"/usr/lib/python3.9/multiprocessing/connection.py\", line 366, in _close\n",
      "    _close(self._handle)\n",
      "  File \"/usr/lib/python3.9/multiprocessing/connection.py\", line 366, in _close\n",
      "    _close(self._handle)\n",
      "  File \"/usr/lib/python3.9/multiprocessing/connection.py\", line 366, in _close\n",
      "    _close(self._handle)\n",
      "OSError: [Errno 9] Bad file descriptor\n",
      "  File \"/usr/lib/python3.9/multiprocessing/connection.py\", line 366, in _close\n",
      "    _close(self._handle)\n",
      "  File \"/usr/lib/python3.9/multiprocessing/connection.py\", line 182, in close\n",
      "    self._close()\n",
      "  File \"/usr/lib/python3.9/multiprocessing/connection.py\", line 366, in _close\n",
      "    _close(self._handle)\n",
      "OSError: [Errno 9] Bad file descriptor\n",
      "OSError: [Errno 9] Bad file descriptor\n",
      "OSError: [Errno 9] Bad file descriptor\n",
      "  File \"/usr/lib/python3.9/multiprocessing/connection.py\", line 366, in _close\n",
      "    _close(self._handle)\n",
      "  File \"/usr/lib/python3.9/multiprocessing/connection.py\", line 366, in _close\n",
      "    _close(self._handle)\n",
      "  File \"/usr/lib/python3.9/multiprocessing/connection.py\", line 366, in _close\n",
      "    _close(self._handle)\n",
      "OSError: [Errno 9] Bad file descriptor\n",
      "  File \"/usr/lib/python3.9/multiprocessing/connection.py\", line 182, in close\n",
      "    self._close()\n",
      "  File \"/usr/lib/python3.9/multiprocessing/connection.py\", line 182, in close\n",
      "    self._close()\n",
      "  File \"/usr/lib/python3.9/multiprocessing/connection.py\", line 366, in _close\n",
      "    _close(self._handle)\n",
      "  File \"/usr/lib/python3.9/multiprocessing/connection.py\", line 366, in _close\n",
      "    _close(self._handle)\n",
      "OSError: [Errno 9] Bad file descriptor\n",
      "  File \"/usr/lib/python3.9/multiprocessing/connection.py\", line 182, in close\n",
      "    self._close()\n",
      "Validation:  10%|▉         | 6/61 [00:06<00:27,  2.00batch/s]OSError: [Errno 9] Bad file descriptor\n",
      "  File \"/usr/lib/python3.9/multiprocessing/queues.py\", line 241, in _feed\n",
      "    close()\n",
      "  File \"/usr/lib/python3.9/multiprocessing/connection.py\", line 182, in close\n",
      "    self._close()\n",
      "  File \"/usr/lib/python3.9/multiprocessing/connection.py\", line 182, in close\n",
      "    self._close()\n",
      "  File \"/usr/lib/python3.9/multiprocessing/connection.py\", line 366, in _close\n",
      "    _close(self._handle)\n",
      "  File \"/usr/lib/python3.9/multiprocessing/connection.py\", line 366, in _close\n",
      "    _close(self._handle)\n",
      "  File \"/usr/lib/python3.9/multiprocessing/connection.py\", line 182, in close\n",
      "    self._close()\n",
      "OSError: [Errno 9] Bad file descriptor\n",
      "  File \"/usr/lib/python3.9/multiprocessing/connection.py\", line 366, in _close\n",
      "    _close(self._handle)\n",
      "OSError: [Errno 9] Bad file descriptor\n",
      "  File \"/usr/lib/python3.9/multiprocessing/connection.py\", line 366, in _close\n",
      "    _close(self._handle)\n",
      "OSError: [Errno 9] Bad file descriptor\n",
      "  File \"/usr/lib/python3.9/multiprocessing/connection.py\", line 182, in close\n",
      "    self._close()\n",
      "  File \"/usr/lib/python3.9/multiprocessing/connection.py\", line 182, in close\n",
      "    self._close()\n",
      "OSError: [Errno 9] Bad file descriptor\n",
      "OSError: [Errno 9] Bad file descriptor\n",
      "OSError: [Errno 9] Bad file descriptor\n",
      "  File \"/usr/lib/python3.9/multiprocessing/connection.py\", line 366, in _close\n",
      "    _close(self._handle)\n",
      "OSError: [Errno 9] Bad file descriptor\n",
      "OSError: [Errno 9] Bad file descriptor\n",
      "  File \"/usr/lib/python3.9/multiprocessing/connection.py\", line 366, in _close\n",
      "    _close(self._handle)\n",
      "  File \"/usr/lib/python3.9/multiprocessing/connection.py\", line 366, in _close\n",
      "    _close(self._handle)\n",
      "  File \"/usr/lib/python3.9/multiprocessing/connection.py\", line 366, in _close\n",
      "    _close(self._handle)\n",
      "OSError: [Errno 9] Bad file descriptor\n",
      "  File \"/usr/lib/python3.9/multiprocessing/connection.py\", line 182, in close\n",
      "    self._close()\n",
      "  File \"/usr/lib/python3.9/multiprocessing/connection.py\", line 366, in _close\n",
      "    _close(self._handle)\n",
      "  File \"/usr/lib/python3.9/multiprocessing/connection.py\", line 366, in _close\n",
      "    _close(self._handle)\n",
      "  File \"/usr/lib/python3.9/multiprocessing/connection.py\", line 366, in _close\n",
      "    _close(self._handle)\n",
      "OSError: [Errno 9] Bad file descriptor\n",
      "OSError: [Errno 9] Bad file descriptor\n",
      "OSError: [Errno 9] Bad file descriptor\n",
      "OSError: [Errno 9] Bad file descriptor\n",
      "OSError: [Errno 9] Bad file descriptor\n",
      "OSError: [Errno 9] Bad file descriptor\n",
      "OSError: [Errno 9] Bad file descriptor\n",
      "OSError: [Errno 9] Bad file descriptor\n",
      "OSError: [Errno 9] Bad file descriptor\n",
      "OSError: [Errno 9] Bad file descriptor\n",
      "OSError: [Errno 9] Bad file descriptor\n",
      "  File \"/usr/lib/python3.9/multiprocessing/connection.py\", line 366, in _close\n",
      "    _close(self._handle)\n",
      "OSError: [Errno 9] Bad file descriptor\n",
      "OSError: [Errno 9] Bad file descriptor\n",
      "OSError: [Errno 9] Bad file descriptor\n",
      "OSError: [Errno 9] Bad file descriptor\n",
      "Validation: 100%|██████████| 61/61 [00:38<00:00,  1.59batch/s]\n"
     ]
    },
    {
     "name": "stdout",
     "output_type": "stream",
     "text": [
      "Early Stopping: 4/10 without improvement.\n",
      "Epoch Summary 12: Train Loss: 11.2968, Train Acc.: 0.6105, Val. Loss: 0.6255, Val. Acc.: 0.6515, Val. Precision: 0.6187, Val. Recall: 0.7175, Val. F1: 0.6390\n"
     ]
    },
    {
     "name": "stderr",
     "output_type": "stream",
     "text": [
      "Epoch 13: 100%|██████████| 223/223 [00:50<00:00,  4.39batch/s]\n",
      "Validation: 100%|██████████| 61/61 [00:16<00:00,  3.81batch/s]\n"
     ]
    },
    {
     "name": "stdout",
     "output_type": "stream",
     "text": [
      "Early Stopping: 5/10 without improvement.\n",
      "Epoch Summary 13: Train Loss: 10.9417, Train Acc.: 0.6335, Val. Loss: 0.6585, Val. Acc.: 0.5979, Val. Precision: 0.6103, Val. Recall: 0.7151, Val. F1: 0.5950\n"
     ]
    },
    {
     "name": "stderr",
     "output_type": "stream",
     "text": [
      "Epoch 14: 100%|██████████| 223/223 [00:50<00:00,  4.40batch/s]\n",
      "Validation: 100%|██████████| 61/61 [00:15<00:00,  3.85batch/s]\n"
     ]
    },
    {
     "name": "stdout",
     "output_type": "stream",
     "text": [
      "Early Stopping: 6/10 without improvement.\n",
      "Epoch Summary 14: Train Loss: 11.2579, Train Acc.: 0.6183, Val. Loss: 0.6437, Val. Acc.: 0.6825, Val. Precision: 0.6664, Val. Recall: 0.6736, Val. F1: 0.6613\n"
     ]
    },
    {
     "name": "stderr",
     "output_type": "stream",
     "text": [
      "Epoch 15: 100%|██████████| 223/223 [00:50<00:00,  4.38batch/s]\n",
      "Validation: 100%|██████████| 61/61 [00:15<00:00,  3.86batch/s]\n"
     ]
    },
    {
     "name": "stdout",
     "output_type": "stream",
     "text": [
      "Early Stopping: 7/10 without improvement.\n",
      "Epoch Summary 15: Train Loss: 11.0078, Train Acc.: 0.6338, Val. Loss: 0.6613, Val. Acc.: 0.5918, Val. Precision: 0.5900, Val. Recall: 0.7112, Val. F1: 0.5889\n"
     ]
    },
    {
     "name": "stderr",
     "output_type": "stream",
     "text": [
      "Epoch 16: 100%|██████████| 223/223 [00:50<00:00,  4.38batch/s]\n",
      "Validation: 100%|██████████| 61/61 [00:15<00:00,  3.88batch/s]\n"
     ]
    },
    {
     "name": "stdout",
     "output_type": "stream",
     "text": [
      "Early Stopping: 8/10 without improvement.\n",
      "Epoch Summary 16: Train Loss: 10.9759, Train Acc.: 0.6304, Val. Loss: 0.6574, Val. Acc.: 0.5804, Val. Precision: 0.5957, Val. Recall: 0.7160, Val. F1: 0.5776\n"
     ]
    },
    {
     "name": "stderr",
     "output_type": "stream",
     "text": [
      "Epoch 17: 100%|██████████| 223/223 [00:50<00:00,  4.39batch/s]\n",
      "Validation: 100%|██████████| 61/61 [00:15<00:00,  3.85batch/s]\n"
     ]
    },
    {
     "name": "stdout",
     "output_type": "stream",
     "text": [
      "Early Stopping: 9/10 without improvement.\n",
      "Epoch Summary 17: Train Loss: 10.7976, Train Acc.: 0.6312, Val. Loss: 0.6681, Val. Acc.: 0.6649, Val. Precision: 0.6675, Val. Recall: 0.6734, Val. F1: 0.6472\n"
     ]
    },
    {
     "name": "stderr",
     "output_type": "stream",
     "text": [
      "Epoch 18: 100%|██████████| 223/223 [00:50<00:00,  4.38batch/s]\n",
      "Validation: 100%|██████████| 61/61 [00:15<00:00,  3.83batch/s]\n"
     ]
    },
    {
     "name": "stdout",
     "output_type": "stream",
     "text": [
      "Early Stopping: 10/10 without improvement.\n",
      "Stopping early due to no improvement in validation metric.\n",
      "Testing...\n",
      "Average Test Loss: 0.7472934955358506\n",
      "Confusion Matrix:\n",
      "[[ 89  32   0]\n",
      " [ 52 161  18]\n",
      " [  3  22  18]]\n",
      "Classification Report:\n",
      "              precision    recall  f1-score     support\n",
      "0              0.618056  0.735537  0.671698  121.000000\n",
      "1              0.748837  0.696970  0.721973  231.000000\n",
      "2              0.500000  0.418605  0.455696   43.000000\n",
      "accuracy       0.678481  0.678481  0.678481    0.678481\n",
      "macro avg      0.622298  0.617037  0.616456  395.000000\n",
      "weighted avg   0.681686  0.678481  0.677585  395.000000\n"
     ]
    }
   ],
   "source": [
    "# Training Loop\n",
    "best_val_metric = 0.0\n",
    "patience_counter = 0\n",
    "\n",
    "for epoch in range(config.num_epochs):\n",
    "    avg_train_loss, train_accuracy = ut_t.train_one_epoch(\n",
    "        epoch, model, train_loader, criterion, optimizer, device, scaler\n",
    "    )\n",
    "    avg_val_loss, val_accuracy, val_precision, val_recall, val_f1 = ut_t.evaluate(model, val_loader, criterion, device)\n",
    "    val_metric = val_accuracy\n",
    "\n",
    "    if experiment:\n",
    "        experiment.log_metrics(\n",
    "            {\n",
    "                \"avg_train_loss\": avg_train_loss,\n",
    "                \"train_accuracy\": train_accuracy,\n",
    "                \"avg_val_loss\": avg_val_loss,\n",
    "                \"val_accuracy\": val_accuracy,\n",
    "                \"val_precision\": val_precision,\n",
    "                \"val_recall\": val_recall,\n",
    "                \"val_f1\": val_f1,\n",
    "            },\n",
    "            epoch=epoch,\n",
    "        )\n",
    "\n",
    "    # early stopping\n",
    "    best_val_metric, patience_counter, stop_training = ut_t.check_early_stopping(\n",
    "        val_metric, best_val_metric, patience_counter, model, weights_dir, config\n",
    "    )\n",
    "    if stop_training:\n",
    "        break\n",
    "\n",
    "    # Print epoch summary\n",
    "    ut_t.print_epoch_summary(\n",
    "        epoch, avg_train_loss, train_accuracy, avg_val_loss, val_accuracy, val_precision, val_recall, val_f1\n",
    "    )\n",
    "\n",
    "# Evaluate the best model on the test set\n",
    "print(\"Testing...\")\n",
    "model = ut_t.load_model_test(weights_dir, model, device)\n",
    "(\n",
    "    avg_test_loss,\n",
    "    test_accuracy,\n",
    "    all_labels,\n",
    "    all_preds,\n",
    "    test_precision,\n",
    "    test_recall,\n",
    "    test_f1,\n",
    "    cm_test,\n",
    "    report_df,\n",
    ") = ut_t.test_model(model, test_loader, device, criterion)\n",
    "\n",
    "if experiment:\n",
    "    log_model(experiment, model=model, model_name=config.model_name)\n",
    "    lbls = [value for value in config.label_mapping.values() if value is not None]\n",
    "    unique_lbls = []\n",
    "    for item in lbls:\n",
    "        if item not in unique_lbls:\n",
    "            unique_lbls.append(item)\n",
    "    experiment.log_metrics(\n",
    "        {\n",
    "            \"avg_test_loss\": avg_test_loss,\n",
    "            \"test_accuracy\": test_accuracy,\n",
    "            \"test_precision\": test_precision,\n",
    "            \"test_recall\": test_recall,\n",
    "            \"test_f1\": test_f1,\n",
    "        }\n",
    "    )\n",
    "    experiment.log_confusion_matrix(\n",
    "        matrix=cm_test,\n",
    "        title=\"Confusion Matrix at best val epoch\",\n",
    "        file_name=\"test_confusion_matrix_best_epoch.json\",\n",
    "        labels=unique_lbls,\n",
    "    )\n",
    "\n",
    "    # Calculate the row percentages\n",
    "    row_sums = cm_test.sum(axis=1, keepdims=True)\n",
    "    cm_percentage = cm_test / row_sums * 100\n",
    "\n",
    "    # Create a custom annotation that includes both count and percentage\n",
    "    annotations = np.empty_like(cm_test).astype(str)\n",
    "\n",
    "    for i in range(cm_test.shape[0]):\n",
    "        for j in range(cm_test.shape[1]):\n",
    "            annotations[i, j] = f\"{cm_test[i, j]}\\n({cm_percentage[i, j]:.1f}%)\"\n",
    "    greek_labels = lbs.convert_to_greek_label(unique_lbls)\n",
    "    # Plot the heatmap with the annotations, using cm_percentage for the color mapping\n",
    "    plt.figure(figsize=(5, 5))\n",
    "    sns.heatmap(\n",
    "        cm_percentage,\n",
    "        annot=annotations,\n",
    "        fmt=\"\",\n",
    "        cmap=\"Blues\",\n",
    "        xticklabels=greek_labels,\n",
    "        yticklabels=greek_labels,\n",
    "        cbar=False,\n",
    "    )\n",
    "    plt.title(config.model_name)\n",
    "    plt.xlabel(\"Predicted\")\n",
    "    plt.ylabel(\"True\")\n",
    "\n",
    "    # Save the plot to a file\n",
    "    heatmap_filename = os.path.join(script_dir, \"temp\", \"confusion_matrix_heatmap.png\")\n",
    "    plt.savefig(heatmap_filename)\n",
    "    plt.close()\n",
    "    experiment.log_image(heatmap_filename, name=\"Confusion Matrix Heatmap\")\n",
    "\n",
    "    experiment.log_text(report_df.to_string(), metadata={\"type\": \"Classification Report\"})\n",
    "    csv_file_path = os.path.join(weights_dir, \"classification_report.csv\")\n",
    "    report_df.to_csv(csv_file_path, index=False)\n",
    "    experiment.log_table(\"classification_report.csv\", tabular_data=report_df)\n",
    "\n",
    "# Log some misclassified examples\n",
    "if experiment:\n",
    "    misclassified_indices = [i for i, (pred, label) in enumerate(zip(all_preds, all_labels)) if pred != label]\n",
    "    random.shuffle(misclassified_indices)  # Shuffle to select random samples\n",
    "    for idx in misclassified_indices[:20]:  # Log 20 misclassified examples\n",
    "        img, true_label = test_dataset[idx]\n",
    "        pred_label = all_preds[idx]\n",
    "        experiment.log_image(\n",
    "            img,\n",
    "            name=f\"Misclassified_{idx}_true{unique_lbls[int(true_label)]}_pred{unique_lbls[int(pred_label)]}\",\n",
    "            metadata={\n",
    "                \"predicted_label\": unique_lbls[int(true_label)].title(),\n",
    "                \"true_label\": unique_lbls[int(true_label)].title(),\n",
    "            },\n",
    "        )\n"
   ]
  },
  {
   "cell_type": "code",
   "execution_count": 86,
   "id": "b8819938",
   "metadata": {},
   "outputs": [
    {
     "data": {
      "text/plain": [
       "array([0, 0, 0, ..., 1, 1, 0])"
      ]
     },
     "execution_count": 86,
     "metadata": {},
     "output_type": "execute_result"
    }
   ],
   "source": [
    "encoded_labels"
   ]
  },
  {
   "cell_type": "code",
   "execution_count": 87,
   "id": "9bddd4be",
   "metadata": {},
   "outputs": [
    {
     "data": {
      "text/plain": [
       "array(['Alpha', 'Alpha', 'Alpha', ..., 'Beta', 'Beta', 'Alpha'],\n",
       "      dtype=object)"
      ]
     },
     "execution_count": 87,
     "metadata": {},
     "output_type": "execute_result"
    }
   ],
   "source": [
    "labels"
   ]
  },
  {
   "cell_type": "code",
   "execution_count": 88,
   "id": "d63b3e35",
   "metadata": {},
   "outputs": [
    {
     "data": {
      "text/plain": [
       "array([[[0., 0., 0., ..., 0., 0., 0.],\n",
       "        [0., 0., 0., ..., 0., 0., 0.],\n",
       "        [0., 0., 0., ..., 0., 0., 0.],\n",
       "        ...,\n",
       "        [0., 0., 0., ..., 0., 0., 0.],\n",
       "        [0., 0., 0., ..., 0., 0., 0.],\n",
       "        [0., 0., 0., ..., 0., 0., 0.]],\n",
       "\n",
       "       [[0., 0., 0., ..., 0., 0., 0.],\n",
       "        [0., 0., 0., ..., 0., 0., 0.],\n",
       "        [0., 0., 0., ..., 0., 0., 0.],\n",
       "        ...,\n",
       "        [0., 0., 0., ..., 0., 0., 0.],\n",
       "        [0., 0., 0., ..., 0., 0., 0.],\n",
       "        [0., 0., 0., ..., 0., 0., 0.]],\n",
       "\n",
       "       [[0., 0., 0., ..., 0., 0., 0.],\n",
       "        [0., 0., 0., ..., 0., 0., 0.],\n",
       "        [0., 0., 0., ..., 0., 0., 0.],\n",
       "        ...,\n",
       "        [0., 0., 0., ..., 0., 0., 0.],\n",
       "        [0., 0., 0., ..., 0., 0., 0.],\n",
       "        [0., 0., 0., ..., 0., 0., 0.]],\n",
       "\n",
       "       ...,\n",
       "\n",
       "       [[0., 0., 0., ..., 0., 0., 0.],\n",
       "        [0., 0., 0., ..., 0., 0., 0.],\n",
       "        [0., 0., 0., ..., 0., 0., 0.],\n",
       "        ...,\n",
       "        [0., 0., 0., ..., 0., 0., 0.],\n",
       "        [0., 0., 0., ..., 0., 0., 0.],\n",
       "        [0., 0., 0., ..., 0., 0., 0.]],\n",
       "\n",
       "       [[0., 0., 0., ..., 0., 0., 0.],\n",
       "        [0., 0., 0., ..., 0., 0., 0.],\n",
       "        [0., 0., 0., ..., 0., 0., 0.],\n",
       "        ...,\n",
       "        [0., 0., 0., ..., 0., 0., 0.],\n",
       "        [0., 0., 0., ..., 0., 0., 0.],\n",
       "        [0., 0., 0., ..., 0., 0., 0.]],\n",
       "\n",
       "       [[0., 0., 0., ..., 0., 0., 0.],\n",
       "        [0., 0., 0., ..., 0., 0., 0.],\n",
       "        [0., 0., 0., ..., 0., 0., 0.],\n",
       "        ...,\n",
       "        [0., 0., 0., ..., 0., 0., 0.],\n",
       "        [0., 0., 0., ..., 0., 0., 0.],\n",
       "        [0., 0., 0., ..., 0., 0., 0.]]])"
      ]
     },
     "execution_count": 88,
     "metadata": {},
     "output_type": "execute_result"
    }
   ],
   "source": [
    "images"
   ]
  },
  {
   "cell_type": "code",
   "execution_count": null,
   "id": "9b6c703e",
   "metadata": {},
   "outputs": [],
   "source": []
  }
 ],
 "metadata": {
  "jupytext": {
   "cell_metadata_filter": "-all",
   "main_language": "python",
   "notebook_metadata_filter": "-all"
  },
  "kernelspec": {
   "display_name": "Python 3",
   "language": "python",
   "name": "python3"
  },
  "language_info": {
   "codemirror_mode": {
    "name": "ipython",
    "version": 3
   },
   "file_extension": ".py",
   "mimetype": "text/x-python",
   "name": "python",
   "nbconvert_exporter": "python",
   "pygments_lexer": "ipython3",
   "version": "3.9.5"
  }
 },
 "nbformat": 4,
 "nbformat_minor": 5
}
